Workbook

Sheet About
A1: BObIC - BAU Output by ISIC Code
A3: State: Oklahoma (OK) Base year: 2019 Pipeline: EPS IO Pipeline — stateior-based
A4: Deflator: 2019 USD -> 2012 USD = 1.12266 (BEA chained GDP price index; 2012 = 100.000, 2019 = 112.266)
A6: =========================================================
A7: Methodology
A8: =========================================================
A9: State industry output is pulled directly from EPA stateior's two-region
A10: (State of Interest vs. Rest of US) MRIO accounts, at BEA Summary sector
A11: resolution. Stateior combines BEA national Make/Use tables with FAF
A12: (Freight Analysis Framework) for goods trade and cluster-based RPC
A13: estimation for services to construct state-level output by industry.
A15: BEA Summary codes are aggregated to the 42-ISIC scheme via the canonical
... A151: - BObIC - looks up each ISIC's STEP 2 value (matches BObIC.csv)

Sheet Keys
A1: category | B1: key | C1: value | D1: description
A2: deflator | B2: deflator_nominal_to_2012 | C2: 1.12266 | D2: Divide nominal 2019 USD by this to get 2012 USD. BEA chained GDP price index; 2012 = 100.000, 2019 = 112.266
A3: year | B3: base_year | C3: 2019 | D3: stateior base year; nominal-USD vintage of the source tabs
A4: numeric | B4: epsilon_div_floor | C4: 1e-09 | D4: Denominator floor for ratio outputs (DCS, ESoP): x/MAX(den, epsilon) avoids div-by-zero; mirrors pmax(den, 1e-9) in the R pipeline
A5: numeric | B5: fogp_denom_floor_usd | C5: 1 | D5: FoGP-entity denominator floor: total purchases per category floored at $1 (mirrors pmax(total, 1)); near-zero totals give near-zero fractions

Sheet 1_Source_IndustryOutput
A1: BEA_Summary_code | B1: output_USD_2019nominal
A2: 111CA | B2: 7.2608211e+09
A3: 113FF | B3: 3.423515e+08
A4: 211 | B4: 3.4073989e+10
A5: 212 | B5: 1.0797283e+09
A6: 213 | B6: 9.2672307e+09
A7: 22 | B7: 6.9256406e+09
A8: 23 | B8: 1.4426657e+10
A9: 321 | B9: 6.192296e+08
A10: 327 | B10: 2.1550942e+09
A11: 331 | B11: 1.4645166e+09
A12: 332 | B12: 6.6696878e+09
A13: 333 | B13: 7.9737559e+09
... A72: GSLE | B72: 3.0839712e+09

Sheet Src_Stateior_SoI_Make
A1: State-of-Interest Make matrix (V) at BEA Summary resolution, from EPA
A2: stateior's two-region MRIO build for this state and base year. Rows =
A3: industries, columns = commodities. Values are in nominal 2019 USD as
A4: emitted by stateior. This is the raw input aggregated to 42 ISIC for
A5: the final output in this workbook.
A8: industry | B8: 111CA | C8: 113FF | D8: 211 | E8: 212 | F8: 213 | G8: 22 | H8: 23 | I8: 321 | J8: 327 | K8: 331 | L8: 332 | M8: 333 | N8: 334 | O8: 335 | P8: 3361MV | Q8: 3364OT | R8: 337 | S8: 339 | T8: 311FT | U8: 313TT | V8: 315AL | W8: 322 | X8: 323 | Y8: 324 | Z8: 325 | AA8: 326 | AB8: 42 | AC8: 441 | AD8: 445 | AE8: 452 | AF8: 4A0 | AG8: 481 | AH8: 482 | AI8: 483 | AJ8: 484 | AK8: 485 | AL8: 486 | AM8: 487OS | AN8: 493 | AO8: 511 | AP8: 512 | AQ8: 513 | AR8: 514 | AS8: 521CI | AT8: 523 | AU8: 524 | AV8: 525 | AW8: HS | AX8: ORE | AY8: 532RL | AZ8: 5411 | BA8: 5415 | BB8: 5412OP | BC8: 55 | BD8: 561 | BE8: 562 | BF8: 61 | BG8: 621 | BH8: 622 | BI8: 623 | BJ8: 624 | BK8: 711AS | BL8: 713 | BM8: 721 | BN8: 722 | BO8: 81 | BP8: GFGD | BQ8: GFGN | BR8: GFE | BS8: GSLG | BT8: GSLE | BU8: Used | BV8: Other
A9: 111CA | B9: 7.1262445e+09 | C9: 99092822 | D9: 0 | E9: 0 | F9: 0 | G9: 0 | H9: 0 | I9: 206042.63 | J9: 0 | K9: 0 | L9: 0 | M9: 0 | N9: 0 | O9: 0 | P9: 0 | Q9: 0 | R9: 0 | S9: 0 | T9: 0 | U9: 0 | V9: 0 | W9: 0 | X9: 0 | Y9: 0 | Z9: 0 | AA9: 0 | AB9: 0 | AC9: 0 | AD9: 0 | AE9: 0 | AF9: 0 | AG9: 0 | AH9: 0 | AI9: 0 | AJ9: 0 | AK9: 0 | AL9: 0 | AM9: 0 | AN9: 0 | AO9: 0 | AP9: 0 | AQ9: 0 | AR9: 0 | AS9: 0 | AT9: 0 | AU9: 0 | AV9: 0 | AW9: 0 | AX9: 0 | AY9: 0 | AZ9: 0 | BA9: 0 | BB9: 0 | BC9: 0 | BD9: 0 | BE9: 0 | BF9: 0 | BG9: 0 | BH9: 0 | BI9: 0 | BJ9: 0 | BK9: 0 | BL9: 35277703 | BM9: 0 | BN9: 0 | BO9: 0 | BP9: 0 | BQ9: 0 | BR9: 0 | BS9: 0 | BT9: 0 | BU9: 0 | BV9: 0
A10: 113FF | B10: 47513.466 | C10: 3.4121125e+08 | D10: 0 | E10: 0 | F10: 0 | G10: 0 | H10: 1106162.3 | I10: 0 | J10: 0 | K10: 0 | L10: 0 | M10: 0 | N10: 0 | O10: 0 | P10: 0 | Q10: 0 | R10: 0 | S10: 0 | T10: 0 | U10: 0 | V10: 0 | W10: 0 | X10: 0 | Y10: 0 | Z10: 0 | AA10: 0 | AB10: 0 | AC10: 0 | AD10: 0 | AE10: 0 | AF10: 0 | AG10: 0 | AH10: 0 | AI10: 0 | AJ10: 0 | AK10: 0 | AL10: 0 | AM10: 0 | AN10: 0 | AO10: 0 | AP10: 0 | AQ10: 0 | AR10: 0 | AS10: 0 | AT10: 0 | AU10: 0 | AV10: 0 | AW10: 0 | AX10: 0 | AY10: 0 | AZ10: 0 | BA10: 0 | BB10: 0 | BC10: 0 | BD10: 0 | BE10: 0 | BF10: 0 | BG10: 0 | BH10: 0 | BI10: 0 | BJ10: 0 | BK10: 0 | BL10: 0 | BM10: 0 | BN10: 0 | BO10: 0 | BP10: 0 | BQ10: 0 | BR10: 0 | BS10: 0 | BT10: 0 | BU10: 0 | BV10: 0
A11: 211 | B11: 0 | C11: 0 | D11: 2.7731713e+10 | E11: 9273225 | F11: 2.6195504e+09 | G11: 0 | H11: 2.6633822e+08 | I11: 0 | J11: 0 | K11: 0 | L11: 0 | M11: 14244766 | N11: 0 | O11: 0 | P11: 0 | Q11: 0 | R11: 0 | S11: 0 | T11: 0 | U11: 0 | V11: 0 | W11: 0 | X11: 0 | Y11: 2.9640716e+09 | Z11: 51204433 | AA11: 0 | AB11: 2.4896487e+08 | AC11: 0 | AD11: 0 | AE11: 0 | AF11: 0 | AG11: 0 | AH11: 0 | AI11: 0 | AJ11: 0 | AK11: 0 | AL11: 0 | AM11: 0 | AN11: 0 | AO11: 0 | AP11: 0 | AQ11: 0 | AR11: 0 | AS11: 0 | AT11: 0 | AU11: 0 | AV11: 0 | AW11: 0 | AX11: 0 | AY11: 0 | AZ11: 0 | BA11: 25820941 | BB11: 1.4313089e+08 | BC11: 0 | BD11: 0 | BE11: 0 | BF11: 0 | BG11: 0 | BH11: 0 | BI11: 0 | BJ11: 0 | BK11: 0 | BL11: 0 | BM11: 0 | BN11: 0 | BO11: 0 | BP11: 0 | BQ11: 0 | BR11: 0 | BS11: 0 | BT11: 0 | BU11: 0 | BV11: 0
A12: 212 | B12: 0 | C12: 0 | D12: 0 | E12: 8.9262399e+08 | F12: 56112633 | G12: 0 | H12: 1.0411218e+08 | I12: 0 | J12: 1668499.9 | K12: 0 | L12: 0 | M12: 0 | N12: 0 | O12: 0 | P12: 0 | Q12: 0 | R12: 0 | S12: 0 | T12: 0 | U12: 0 | V12: 0 | W12: 0 | X12: 0 | Y12: 325458.14 | Z12: 19771413 | AA12: 0 | AB12: 4256760.4 | AC12: 0 | AD12: 0 | AE12: 0 | AF12: 0 | AG12: 0 | AH12: 0 | AI12: 0 | AJ12: 0 | AK12: 0 | AL12: 0 | AM12: 0 | AN12: 0 | AO12: 0 | AP12: 0 | AQ12: 0 | AR12: 0 | AS12: 0 | AT12: 0 | AU12: 0 | AV12: 0 | AW12: 0 | AX12: 0 | AY12: 0 | AZ12: 0 | BA12: 26115.094 | BB12: 861798.11 | BC12: 0 | BD12: 0 | BE12: 0 | BF12: 0 | BG12: 0 | BH12: 0 | BI12: 0 | BJ12: 0 | BK12: 0 | BL12: 0 | BM12: 0 | BN12: 0 | BO12: 0 | BP12: 0 | BQ12: 0 | BR12: 0 | BS12: 0 | BT12: 0 | BU12: 0 | BV12: 0
A13: 213 | B13: 0 | C13: 0 | D13: 7213352.6 | E13: 0 | F13: 8.608505e+09 | G13: 0 | H13: 5.7297691e+08 | I13: 0 | J13: 0 | K13: 0 | L13: 18789271 | M13: 0 | N13: 0 | O13: 0 | P13: 0 | Q13: 0 | R13: 0 | S13: 0 | T13: 0 | U13: 0 | V13: 0 | W13: 0 | X13: 0 | Y13: 2009626.3 | Z13: 0 | AA13: 0 | AB13: 31816813 | AC13: 0 | AD13: 0 | AE13: 0 | AF13: 0 | AG13: 0 | AH13: 0 | AI13: 0 | AJ13: 0 | AK13: 0 | AL13: 0 | AM13: 0 | AN13: 0 | AO13: 0 | AP13: 0 | AQ13: 0 | AR13: 0 | AS13: 0 | AT13: 0 | AU13: 0 | AV13: 0 | AW13: 0 | AX13: 0 | AY13: 0 | AZ13: 0 | BA13: 3497106.6 | BB13: 22422625 | BC13: 0 | BD13: 0 | BE13: 0 | BF13: 0 | BG13: 0 | BH13: 0 | BI13: 0 | BJ13: 0 | BK13: 0 | BL13: 0 | BM13: 0 | BN13: 0 | BO13: 0 | BP13: 0 | BQ13: 0 | BR13: 0 | BS13: 0 | BT13: 0 | BU13: 0 | BV13: 0
A14: 22 | B14: 0 | C14: 0 | D14: 346933.28 | E14: 0 | F14: 0 | G14: 6.7507987e+09 | H14: 36600096 | I14: 0 | J14: 0 | K14: 0 | L14: 0 | M14: 0 | N14: 0 | O14: 0 | P14: 0 | Q14: 0 | R14: 0 | S14: 0 | T14: 0 | U14: 0 | V14: 0 | W14: 0 | X14: 0 | Y14: 0 | Z14: 0 | AA14: 0 | AB14: 20045138 | AC14: 0 | AD14: 0 | AE14: 0 | AF14: 12008362 | AG14: 0 | AH14: 0 | AI14: 0 | AJ14: 0 | AK14: 0 | AL14: 38806532 | AM14: 0 | AN14: 0 | AO14: 0 | AP14: 0 | AQ14: 0 | AR14: 0 | AS14: 0 | AT14: 0 | AU14: 0 | AV14: 0 | AW14: 0 | AX14: 0 | AY14: 0 | AZ14: 0 | BA14: 5522776.6 | BB14: 1644797.9 | BC14: 0 | BD14: 0 | BE14: 79513.012 | BF14: 0 | BG14: 0 | BH14: 0 | BI14: 0 | BJ14: 0 | BK14: 0 | BL14: 0 | BM14: 0 | BN14: 0 | BO14: 0 | BP14: 0 | BQ14: 0 | BR14: 0 | BS14: 0 | BT14: 59787734 | BU14: 0 | BV14: 0
A15: 23 | B15: 0 | C15: 0 | D15: 0 | E15: 0 | F15: 0 | G15: 0 | H15: 1.4423459e+10 | I15: 0 | J15: 0 | K15: 0 | L15: 0 | M15: 0 | N15: 0 | O15: 0 | P15: 0 | Q15: 0 | R15: 0 | S15: 0 | T15: 0 | U15: 0 | V15: 0 | W15: 0 | X15: 0 | Y15: 0 | Z15: 0 | AA15: 0 | AB15: 0 | AC15: 0 | AD15: 0 | AE15: 0 | AF15: 0 | AG15: 0 | AH15: 0 | AI15: 0 | AJ15: 0 | AK15: 0 | AL15: 0 | AM15: 0 | AN15: 0 | AO15: 0 | AP15: 0 | AQ15: 0 | AR15: 0 | AS15: 0 | AT15: 0 | AU15: 0 | AV15: 0 | AW15: 0 | AX15: 0 | AY15: 0 | AZ15: 0 | BA15: 3006657.1 | BB15: 191559.87 | BC15: 0 | BD15: 0 | BE15: 0 | BF15: 0 | BG15: 0 | BH15: 0 | BI15: 0 | BJ15: 0 | BK15: 0 | BL15: 0 | BM15: 0 | BN15: 0 | BO15: 0 | BP15: 0 | BQ15: 0 | BR15: 0 | BS15: 0 | BT15: 0 | BU15: 0 | BV15: 0
A16: 321 | B16: 0 | C16: 0 | D16: 0 | E16: 0 | F16: 0 | G16: 0 | H16: 2526142.3 | I16: 6.0730425e+08 | J16: 271312.58 | K16: 0 | L16: 712091.43 | M16: 0 | N16: 0 | O16: 0 | P16: 0 | Q16: 0 | R16: 2277043 | S16: 0 | T16: 0 | U16: 0 | V16: 0 | W16: 29608.013 | X16: 0 | Y16: 0 | Z16: 80465.507 | AA16: 119762.95 | AB16: 4420748.9 | AC16: 0 | AD16: 0 | AE16: 0 | AF16: 0 | AG16: 0 | AH16: 0 | AI16: 0 | AJ16: 0 | AK16: 0 | AL16: 0 | AM16: 0 | AN16: 0 | AO16: 0 | AP16: 0 | AQ16: 0 | AR16: 0 | AS16: 0 | AT16: 0 | AU16: 0 | AV16: 0 | AW16: 0 | AX16: 0 | AY16: 0 | AZ16: 0 | BA16: 78495.946 | BB16: 378207.74 | BC16: 0 | BD16: 0 | BE16: 0 | BF16: 0 | BG16: 0 | BH16: 0 | BI16: 0 | BJ16: 0 | BK16: 0 | BL16: 0 | BM16: 0 | BN16: 0 | BO16: 0 | BP16: 0 | BQ16: 0 | BR16: 0 | BS16: 0 | BT16: 0 | BU16: 1020447.3 | BV16: 0
A17: 327 | B17: 0 | C17: 0 | D17: 0 | E17: 6217649.7 | F17: 0 | G17: 0 | H17: 15971510 | I17: 355424.14 | J17: 2.0856557e+09 | K17: 17305.718 | L17: 506809.75 | M17: 53573.667 | N17: 0 | O17: 2177419.9 | P17: 155939.13 | Q17: 4005.3204 | R17: 1998212.3 | S17: 221012.28 | T17: 0 | U17: 474718.99 | V17: 175539.24 | W17: 314593.96 | X17: 0 | Y17: 457054.35 | Z17: 1106144.3 | AA17: 1107557.9 | AB17: 23062596 | AC17: 0 | AD17: 0 | AE17: 0 | AF17: 0 | AG17: 0 | AH17: 0 | AI17: 0 | AJ17: 0 | AK17: 0 | AL17: 0 | AM17: 0 | AN17: 0 | AO17: 0 | AP17: 0 | AQ17: 0 | AR17: 0 | AS17: 0 | AT17: 0 | AU17: 0 | AV17: 0 | AW17: 0 | AX17: 0 | AY17: 0 | AZ17: 0 | BA17: 695854.18 | BB17: 14331283 | BC17: 0 | BD17: 0 | BE17: 0 | BF17: 0 | BG17: 0 | BH17: 0 | BI17: 0 | BJ17: 0 | BK17: 0 | BL17: 0 | BM17: 0 | BN17: 0 | BO17: 0 | BP17: 0 | BQ17: 0 | BR17: 0 | BS17: 0 | BT17: 0 | BU17: 66271.827 | BV17: 0
A18: 331 | B18: 0 | C18: 0 | D18: 0 | E18: 0 | F18: 0 | G18: 0 | H18: 959741.58 | I18: 0 | J18: 383132.7 | K18: 1.4454553e+09 | L18: 5580296.2 | M18: 471164.66 | N18: 4521.3548 | O18: 1176881.6 | P18: 0 | Q18: 0 | R18: 0 | S18: 0 | T18: 0 | U18: 9309.4414 | V18: 0 | W18: 3388.4426 | X18: 0 | Y18: 1556864.7 | Z18: 908748.21 | AA18: 0 | AB18: 3799952.4 | AC18: 0 | AD18: 0 | AE18: 0 | AF18: 0 | AG18: 0 | AH18: 0 | AI18: 0 | AJ18: 0 | AK18: 0 | AL18: 0 | AM18: 0 | AN18: 0 | AO18: 0 | AP18: 0 | AQ18: 0 | AR18: 0 | AS18: 0 | AT18: 0 | AU18: 0 | AV18: 0 | AW18: 0 | AX18: 0 | AY18: 0 | AZ18: 0 | BA18: 374533.3 | BB18: 1837554 | BC18: 0 | BD18: 0 | BE18: 0 | BF18: 0 | BG18: 0 | BH18: 0 | BI18: 0 | BJ18: 0 | BK18: 0 | BL18: 0 | BM18: 0 | BN18: 0 | BO18: 0 | BP18: 0 | BQ18: 0 | BR18: 0 | BS18: 0 | BT18: 0 | BU18: 2001412.3 | BV18: 0
A19: 332 | B19: 0 | C19: 0 | D19: 0 | E19: 0 | F19: 0 | G19: 0 | H19: 48920378 | I19: 5284038.9 | J19: 3466049.8 | K19: 67955697 | L19: 6.2789125e+09 | M19: 26602238 | N19: 10344051 | O19: 4211940.4 | P19: 6799152.7 | Q19: 1132162 | R19: 1219474.5 | S19: 6831616.5 | T19: 0 | U19: 2401992.6 | V19: 0 | W19: 15429.649 | X19: 1254368.7 | Y19: 16461.64 | Z19: 787509.3 | AA19: 4418618.7 | AB19: 68861150 | AC19: 0 | AD19: 0 | AE19: 0 | AF19: 0 | AG19: 0 | AH19: 0 | AI19: 0 | AJ19: 0 | AK19: 0 | AL19: 0 | AM19: 0 | AN19: 0 | AO19: 0 | AP19: 0 | AQ19: 0 | AR19: 0 | AS19: 0 | AT19: 0 | AU19: 0 | AV19: 0 | AW19: 0 | AX19: 0 | AY19: 0 | AZ19: 0 | BA19: 5976697.7 | BB19: 53974746 | BC19: 0 | BD19: 0 | BE19: 0 | BF19: 0 | BG19: 0 | BH19: 0 | BI19: 0 | BJ19: 0 | BK19: 0 | BL19: 0 | BM19: 0 | BN19: 0 | BO19: 7452425.6 | BP19: 0 | BQ19: 0 | BR19: 0 | BS19: 0 | BT19: 0 | BU19: 62884453 | BV19: 0
A20: 333 | B20: 0 | C20: 0 | D20: 0 | E20: 0 | F20: 28590.74 | G20: 0 | H20: 18812707 | I20: 0 | J20: 982385.37 | K20: 475170.16 | L20: 40228656 | M20: 7.403988e+09 | N20: 16564839 | O20: 36115418 | P20: 11675293 | Q20: 5332354.3 | R20: 280288.71 | S20: 3769244.4 | T20: 0 | U20: 0 | V20: 0 | W20: 0 | X20: 0 | Y20: 0 | Z20: 3539456.6 | AA20: 149413.57 | AB20: 1.4475491e+08 | AC20: 0 | AD20: 0 | AE20: 0 | AF20: 0 | AG20: 0 | AH20: 0 | AI20: 0 | AJ20: 0 | AK20: 0 | AL20: 0 | AM20: 0 | AN20: 0 | AO20: 0 | AP20: 0 | AQ20: 0 | AR20: 0 | AS20: 0 | AT20: 0 | AU20: 0 | AV20: 0 | AW20: 0 | AX20: 0 | AY20: 371679.62 | AZ20: 0 | BA20: 17869212 | BB20: 2.599756e+08 | BC20: 0 | BD20: 0 | BE20: 0 | BF20: 0 | BG20: 0 | BH20: 0 | BI20: 0 | BJ20: 0 | BK20: 0 | BL20: 0 | BM20: 0 | BN20: 0 | BO20: 0 | BP20: 0 | BQ20: 0 | BR20: 0 | BS20: 0 | BT20: 0 | BU20: 8863129.3 | BV20: 0
... A79: GSLE | B79: 0 | C79: 0 | D79: 0 | E79: 0 | F79: 0 | G79: 1.1902627e+09 | H79: 0 | I79: 0 | J79: 0 | K79: 0 | L79: 0 | M79: 0 | N79: 0 | O79: 0 | P79: 0 | Q79: 0 | R79: 0 | S79: 0 | T79: 0 | U79: 0 | V79: 0 | W79: 0 | X79: 0 | Y79: 0 | Z79: 0 | AA79: 0 | AB79: 0 | AC79: 0 | AD79: 46534014 | AE79: 0 | AF79: 0 | AG79: 0 | AH79: 1064556.3 | AI79: 3709817.4 | AJ79: 0 | AK79: 1.4015045e+08 | AL79: 0 | AM79: 1.2806935e+08 | AN79: 0 | AO79: 0 | AP79: 0 | AQ79: 0 | AR79: 0 | AS79: 169361.23 | AT79: 0 | AU79: 3516261.7 | AV79: 0 | AW79: 68800984 | AX79: 2.3332332e+08 | AY79: 0 | AZ79: 0 | BA79: 0 | BB79: 0 | BC79: 0 | BD79: 0 | BE79: 0 | BF79: 0 | BG79: 0 | BH79: 0 | BI79: 0 | BJ79: 0 | BK79: 798417.23 | BL79: 3.5203748e+08 | BM79: 0 | BN79: 0 | BO79: 26742945 | BP79: 0 | BQ79: 0 | BR79: 0 | BS79: 0 | BT79: 8.8879967e+08 | BU79: 0 | BV79: 0

Sheet Src_Disagg_EIA_coal
A1: Raw EIA Annual Coal Report (Form EIA-7A) 2019 state production values,
A2: used as the numerator for the 212 BEA mining disagg split (05 coal vs
A3: 07T08 other mining). Source:
A4: https://www.eia.gov/coal/annual/
A6: THIS STATE: OK
A9: state | B9: short_tons | C9: short_tons_units | D9: value_usd | E9: source_notes
A10: AL | B10: 12031000 | C10: short tons | D10: 600000000 | E10: EIA Annual Coal Report 2019; AL avg ~$50/ton bituminous
A11: AK | B11: 1000000 | C11: short tons | D11: 40000000 | E11: EIA Annual Coal Report 2019; AK Usibelli ~$40/ton subbit
A12: AZ | B12: 4220000 | C12: short tons | D12: 125000000 | E12: EIA Annual Coal Report 2019; Kayenta mine closed 2019; partial year
A13: AR | B13: 0 | C13: short tons | D13: 0
A14: CA | B14: 0 | C14: short tons | D14: 0
A15: CO | B15: 10710000 | C15: short tons | D15: 330000000 | E15: EIA ~$31/ton
A16: CT | B16: 0 | C16: short tons | D16: 0
A17: DE | B17: 0 | C17: short tons | D17: 0
A18: DC | B18: 0 | C18: short tons | D18: 0
A19: FL | B19: 0 | C19: short tons | D19: 0
A20: GA | B20: 0 | C20: short tons | D20: 0
A21: HI | B21: 0 | C21: short tons | D21: 0
A22: ID | B22: 0 | C22: short tons | D22: 0
A23: IL | B23: 45919000 | C23: short tons | D23: 1950000000 | E23: IL Basin avg ~$42/ton
A24: IN | B24: 28820000 | C24: short tons | D24: 1210000000 | E24: IL Basin avg ~$42/ton
A25: IA | B25: 0 | C25: short tons | D25: 0
A26: KS | B26: 0 | C26: short tons | D26: 0
A27: KY | B27: 36140000 | C27: short tons | D27: 1730000000 | E27: KY split East (Central App ~$58/ton) + West (IL Basin ~$40/ton)
A28: LA | B28: 2720000 | C28: short tons | D28: 60000000 | E28: lignite ~$22/ton
A29: ME | B29: 0 | C29: short tons | D29: 0
A30: MD | B30: 1320000 | C30: short tons | D30: 70000000 | E30: NA Appalachia ~$55/ton
A31: MA | B31: 0 | C31: short tons | D31: 0
A32: MI | B32: 0 | C32: short tons | D32: 0
A33: MN | B33: 0 | C33: short tons | D33: 0
A34: MS | B34: 2800000 | C34: short tons | D34: 65000000 | E34: lignite
A35: MO | B35: 264000 | C35: short tons | D35: 12000000
A36: MT | B36: 38660000 | C36: short tons | D36: 590000000 | E36: PRB subbit ~$14/ton + some bituminous
A37: NE | B37: 0 | C37: short tons | D37: 0
A38: NV | B38: 0 | C38: short tons | D38: 0
A39: NH | B39: 0 | C39: short tons | D39: 0
A40: NJ | B40: 0 | C40: short tons | D40: 0
A41: NM | B41: 10720000 | C41: short tons | D41: 260000000 | E41: San Juan + McKinley ~$24/ton
A42: NY | B42: 0 | C42: short tons | D42: 0
A43: NC | B43: 0 | C43: short tons | D43: 0
...

Sheet Src_Disagg_heuristics
A1: Hand-curated heuristic tables used as layer-3 fallback for BEA 327
A2: (nonmetallic) / 331 (primary metals) / 325 (chemicals) disaggregation
A3: when Census ASM is suppressed and GHGRP lacks coverage.
A5: Sources:
A6: - cement-heavy state list: GHGRP Subpart H 2019 facility presence
A7: + USGS Minerals Yearbook 2019 cement production rankings
A8: - glass-heavy state list: Census ASM 2017 NAICS 3272 top-6 states
A9: - steel_share: Census ASM 2017 NAICS 331 VA breakdown (2021 SUSB
A10: supplement where suppressed) + industry knowledge
A11: - pharma_share: Census ASM 2017 NAICS 325 VA breakdown +
A12: BLS QCEW 2019 NAICS 3254 employment share
A14: See R/build_state_overrides.R for the applied logic.
... A23: 331 / 325 heuristic split shares (used only where Census ASM / GHGRP unavailable):
A25: state | B25: 331_steel_share (-> ISIC 241) | C25: 331_other_share (-> ISIC 242) | D25: 325_pharma_share (-> ISIC 21) | E25: 325_chem_share (-> ISIC 20)
A26: AK | B26: 0.4 | C26: 0.6 | D26: 0.3 | E26: 0.7
A27: AL | B27: 0.7 | C27: 0.3 | D27: 0.15 | E27: 0.85
A28: AR | B28: 0.5 | C28: 0.5 | D28: 0.1 | E28: 0.9
A29: AZ | B29: 0.3 | C29: 0.7 | D29: 0.2 | E29: 0.8
A30: CA | B30: 0.35 | C30: 0.65 | D30: 0.55 | E30: 0.45
A31: CO | B31: 0.5 | C31: 0.5 | D31: 0.3 | E31: 0.7
A32: CT | B32: 0.4 | C32: 0.6 | D32: 0.5 | E32: 0.5
A33: DC | B33: 0.4 | C33: 0.6 | D33: 0.3 | E33: 0.7
A34: DE | B34: 0.5 | C34: 0.5 | D34: 0.4 | E34: 0.6
A35: FL | B35: 0.35 | C35: 0.65 | D35: 0.4 | E35: 0.6
A36: GA | B36: 0.5 | C36: 0.5 | D36: 0.3 | E36: 0.7
A37: HI | B37: 0.4 | C37: 0.6 | D37: 0.3 | E37: 0.7
... A76: WY | B76: 0.3 | C76: 0.7 | D76: 0.1 | E76: 0.9

Sheet Crosswalk_BEA_to_ISIC
A1: BEA Summary (post-disagg) -> 42-ISIC crosswalk, applied to state OK.
A3: Rows with allocation_weight != 1.0 represent BEA sectors that are split
A4: across multiple ISIC codes (e.g. BEA 22 utilities -> 351/352T353/36T39).
A5: State-specific overrides are loaded from crosswalks/state_overrides/<ST>/splits.csv.
A8: BEA_code | B8: BEA_name | C8: ISIC_code | D8: ISIC_name | E8: allocation_weight | F8: notes | G8: source
A9: 111CA | B9: Farms | C9: 01T03 | D9: Agriculture, forestry, fishing | E9: 1
A10: 113FF | B10: Forestry, fishing, related | C10: 01T03 | D10: Agriculture, forestry, fishing | E10: 1
A11: 211 | B11: Oil and gas extraction | C11: 06 | D11: Extraction of crude petroleum and natural gas | E11: 1
A12: 213 | B12: Support activities for mining | C12: 09 | D12: Mining support service activities | E12: 1
A13: 22 | B13: Utilities | C13: 351 | D13: Electricity | E13: 0.72 | F13: BEA 2012 Detail: electric ~72% of 22 output
A14: 22 | B14: Utilities | C14: 352T353 | D14: Gas, steam, AC | E14: 0.2 | F14: BEA Detail: gas distribution ~20%
A15: 22 | B15: Utilities | C15: 36T39 | D15: Water, sewerage, waste | E15: 0.08 | F15: BEA Detail: water/sewage ~8%
A16: 23 | B16: Construction | C16: 41T43 | D16: Construction | E16: 1
A17: 311FT | B17: Food, beverage, tobacco | C17: 10T12 | D17: Food, beverages, tobacco | E17: 1
A18: 313TT | B18: Textile mills and textile product mills | C18: 13T15 | D18: Textiles, apparel, leather | E18: 1
A19: 315AL | B19: Apparel and leather | C19: 13T15 | D19: Textiles, apparel, leather | E19: 1
A20: 321 | B20: Wood products | C20: 16 | D20: Wood and products of wood and cork | E20: 1
A21: 322 | B21: Paper products | C21: 17T18 | D21: Paper products and printing | E21: 1
A22: 323 | B22: Printing and related | C22: 17T18 | D22: Paper products and printing | E22: 1
A23: 324 | B23: Petroleum and coal products | C23: 19 | D23: Coke and refined petroleum products | E23: 0.961 | F23: BEA 2024 Detail: 324110 refineries + 324121/324122 asphalt = ~96.1% of 324 output ($601,241M / $625,936M)
A24: 324 | B24: Petroleum and coal products | C24: 241 | D24: Iron and steel (incl. coal coking) | E24: 0.039 | F24: EPS modeling convention: route NAICS 324190 (Other petroleum and coal products mfg, includes coal coking) to 241 to consolidate coke with iron and steel; matches eps-us national model
A25: 326 | B25: Plastics and rubber products | C25: 22 | D25: Rubber and plastics products | E25: 1
A26: 332 | B26: Fabricated metal products | C26: 25 | D26: Fabricated metal products | E26: 1
A27: 333 | B27: Machinery | C27: 28 | D27: Machinery and equipment n.e.c. | E27: 1
A28: 334 | B28: Computer and electronic products | C28: 26 | D28: Computer, electronic and optical products | E28: 1
A29: 335 | B29: Electrical equipment, appliances | C29: 27 | D29: Electrical equipment | E29: 1
A30: 3361MV | B30: Motor vehicles, bodies, trailers, parts | C30: 29 | D30: Motor vehicles, trailers, semi-trailers | E30: 1
A31: 3364OT | B31: Other transportation equipment | C31: 30 | D31: Other transport equipment | E31: 1
A32: 337 | B32: Furniture and related products | C32: 31T33 | D32: Furniture; other manufacturing; repair | E32: 1
A33: 339 | B33: Miscellaneous manufacturing | C33: 31T33 | D33: Furniture; other manufacturing; repair | E33: 1
A34: 42 | B34: Wholesale trade | C34: 45T47 | D34: Wholesale and retail trade | E34: 1
A35: 441 | B35: Motor vehicle and parts dealers | C35: 45T47 | D35: Wholesale and retail trade | E35: 1
A36: 445 | B36: Food and beverage stores | C36: 45T47 | D36: Wholesale and retail trade | E36: 1
... A43: 485 | B43: Transit and ground passenger | C43: 49T53 | D43: Transportation and storage | E43: 1
A44: 486 | B44: Pipeline transportation | C44: 352T353 | D44: Gas, steam, AC (incl. pipelines per EPS energy-side convention) | E44: 1 | F44: Reclassified from 49T53 (staff decision 2026-07-16): EPS 352T353 = 'energy pipelines and gas processing'; industrial-energy side sources pipeline fuel (AEO T36 / NAICS 486) here, so IO dollars follow. NOTE: diverges from eps-us national io-model (tags 486 -> 49T53); national files to be corrected separately.
A45: 487OS | B45: Other transportation and support | C45: 49T53 | D45: Transportation and storage | E45: 1
A46: 493 | B46: Warehousing and storage | C46: 49T53 | D46: Transportation and storage | E46: 1
A47: 511 | B47: Publishing industries (incl software) | C47: 58T60 | D47: Publishing, audiovisual, broadcasting | E47: 1
A48: 512 | B48: Motion picture and sound recording | C48: 58T60 | D48: Publishing, audiovisual, broadcasting | E48: 1
A49: 513 | B49: Broadcasting and telecom | C49: 58T60 | D49: Publishing, audiovisual, broadcasting | E49: 0.25 | F49: Placeholder ~25/75 broadcast/telecom per \u00a74.6
...

Sheet State_disagg_splits
A1: State-specific disaggregation ratios applied for OK.
A3: Five BEA Summary sectors are split into finer ISIC children. Ratios
A4: come from the layered proxy strategy in the migration plan (sec 4.0):
A5: 1. Pulled-from-source data (EIA-7A, Census ASM, GHGRP) where available
A6: 2. GHGRP emissions proxy where Census is suppressed
A7: 3. Hand-curated heuristic table (from industry knowledge)
A8: 4. National fallback ratio (last resort)
A11: BEA_code | B11: ISIC_code | C11: allocation_weight | D11: source
A12: 212 | B12: 05 | C12: 0.042972192 | D12: coal/(coal+nonfuel) mine-value share, 2012 USD: EIA coal 2019 $36M + USGS T3 nonfuel 2021 $794M -> coal share 0.043 (applied to stateior 212 $1080M)
A13: 212 | B13: 07T08 | C13: 0.95702781 | D13: coal/(coal+nonfuel) mine-value share, 2012 USD: EIA coal 2019 $36M + USGS T3 nonfuel 2021 $794M -> coal share 0.043 (applied to stateior 212 $1080M)
A14: 327 | B14: 231 | C14: 0.1 | D14: HEURISTIC (GHGRP Subpart H cement state list + glass industry profile; Census ASM suppressed or missing)
A15: 327 | B15: 239 | C15: 0.9 | D15: HEURISTIC (GHGRP Subpart H cement state list + glass industry profile; Census ASM suppressed or missing)
A16: 331 | B16: 241 | C16: 0.45 | D16: HEURISTIC (no ASM or GHGRP data pulled yet)
A17: 331 | B17: 242 | C17: 0.55 | D17: HEURISTIC (no ASM or GHGRP data pulled yet)
A18: 325 | B18: 20 | C18: 0.85 | D18: HEURISTIC (Census ASM suppressed or unpulled)
A19: 325 | B19: 21 | C19: 0.15 | D19: HEURISTIC (Census ASM suppressed or unpulled)

Sheet NAICS_to_ISIC_Key
A1: Concise NAICS Summary -> ISIC Rev 4 mapping used by this pipeline.
A2: See US Census Bureau NAICS 2017 to ISIC Rev 4 concordance for the full
A3: detail-level mapping:
A4: https://www.census.gov/naics/concordances/2017_NAICS_to_ISIC_4.xlsx
A7: ISIC Rev 4 code | B7: Title (42-ISIC scheme) | C7: BEA Summary sources (examples)
A8: 01T03 | B8: Agriculture, forestry and fishing | C8: 111CA Farms; 113FF Forestry/fishing/related
A9: 05 | B9: Mining of coal and lignite | C9: 212/coal (NAICS 2121)
A10: 06 | B10: Extraction of crude petroleum and natural gas | C10: 211 Oil and gas extraction
A11: 07T08 | B11: Mining of metal ores; other mining and quarrying | C11: 212/other (NAICS 2122+2123)
A12: 09 | B12: Mining support service activities | C12: 213 Support activities for mining
A13: 10T12 | B13: Food products, beverages and tobacco | C13: 311FT Food/beverage/tobacco
A14: 13T15 | B14: Textiles, wearing apparel, leather and related products | C14: 313TT Textile mills; 315AL Apparel/leather
A15: 16 | B15: Wood and products of wood and cork, except furniture | C15: 321 Wood products
A16: 17T18 | B16: Paper products and printing | C16: 322 Paper; 323 Printing
A17: 19 | B17: Coke and refined petroleum products | C17: 324 Petroleum and coal products
A18: 20 | B18: Chemicals and chemical products (excl. pharmaceuticals) | C18: 325/chem (NAICS 3251-3259 excl. 3254)
... A49: 97T98 | B49: Households as employers; undifferentiated production (zero in EPS) | C49: Designed zero row: households as employers (NAICS 814)

Sheet 5_Calc_ISIC_aggregation
A1: STEP 1 - read BEA code / ISIC code / weight live from the Crosswalk tab, pull each BEA value from the source tab, then weight it
A2: BEA_code | B2: ISIC_code | C2: allocation_weight | D2: BEA_value_nominal | E2: weighted_nominal
A3: ='Crosswalk_BEA_to_ISIC'!A9 | B3: ='Crosswalk_BEA_to_ISIC'!C9 | C3: ='Crosswalk_BEA_to_ISIC'!E9 | D3: =IFERROR(INDEX('1_Source_IndustryOutput'!$B$2:$B$72, MATCH($A3, '1_Source_IndustryOutput'!$A$2:$A$72, 0)), 0) | E3: =C3*D3
A4: ='Crosswalk_BEA_to_ISIC'!A10 | B4: ='Crosswalk_BEA_to_ISIC'!C10 | C4: ='Crosswalk_BEA_to_ISIC'!E10 | D4: =IFERROR(INDEX('1_Source_IndustryOutput'!$B$2:$B$72, MATCH($A4, '1_Source_IndustryOutput'!$A$2:$A$72, 0)), 0) | E4: =C4*D4
A5: ='Crosswalk_BEA_to_ISIC'!A11 | B5: ='Crosswalk_BEA_to_ISIC'!C11 | C5: ='Crosswalk_BEA_to_ISIC'!E11 | D5: =IFERROR(INDEX('1_Source_IndustryOutput'!$B$2:$B$72, MATCH($A5, '1_Source_IndustryOutput'!$A$2:$A$72, 0)), 0) | E5: =C5*D5
A6: ='Crosswalk_BEA_to_ISIC'!A12 | B6: ='Crosswalk_BEA_to_ISIC'!C12 | C6: ='Crosswalk_BEA_to_ISIC'!E12 | D6: =IFERROR(INDEX('1_Source_IndustryOutput'!$B$2:$B$72, MATCH($A6, '1_Source_IndustryOutput'!$A$2:$A$72, 0)), 0) | E6: =C6*D6
A7: ='Crosswalk_BEA_to_ISIC'!A13 | B7: ='Crosswalk_BEA_to_ISIC'!C13 | C7: ='Crosswalk_BEA_to_ISIC'!E13 | D7: =IFERROR(INDEX('1_Source_IndustryOutput'!$B$2:$B$72, MATCH($A7, '1_Source_IndustryOutput'!$A$2:$A$72, 0)), 0) | E7: =C7*D7
A8: ='Crosswalk_BEA_to_ISIC'!A14 | B8: ='Crosswalk_BEA_to_ISIC'!C14 | C8: ='Crosswalk_BEA_to_ISIC'!E14 | D8: =IFERROR(INDEX('1_Source_IndustryOutput'!$B$2:$B$72, MATCH($A8, '1_Source_IndustryOutput'!$A$2:$A$72, 0)), 0) | E8: =C8*D8
A9: ='Crosswalk_BEA_to_ISIC'!A15 | B9: ='Crosswalk_BEA_to_ISIC'!C15 | C9: ='Crosswalk_BEA_to_ISIC'!E15 | D9: =IFERROR(INDEX('1_Source_IndustryOutput'!$B$2:$B$72, MATCH($A9, '1_Source_IndustryOutput'!$A$2:$A$72, 0)), 0) | E9: =C9*D9
A10: ='Crosswalk_BEA_to_ISIC'!A16 | B10: ='Crosswalk_BEA_to_ISIC'!C16 | C10: ='Crosswalk_BEA_to_ISIC'!E16 | D10: =IFERROR(INDEX('1_Source_IndustryOutput'!$B$2:$B$72, MATCH($A10, '1_Source_IndustryOutput'!$A$2:$A$72, 0)), 0) | E10: =C10*D10
A11: ='Crosswalk_BEA_to_ISIC'!A17 | B11: ='Crosswalk_BEA_to_ISIC'!C17 | C11: ='Crosswalk_BEA_to_ISIC'!E17 | D11: =IFERROR(INDEX('1_Source_IndustryOutput'!$B$2:$B$72, MATCH($A11, '1_Source_IndustryOutput'!$A$2:$A$72, 0)), 0) | E11: =C11*D11
A12: ='Crosswalk_BEA_to_ISIC'!A18 | B12: ='Crosswalk_BEA_to_ISIC'!C18 | C12: ='Crosswalk_BEA_to_ISIC'!E18 | D12: =IFERROR(INDEX('1_Source_IndustryOutput'!$B$2:$B$72, MATCH($A12, '1_Source_IndustryOutput'!$A$2:$A$72, 0)), 0) | E12: =C12*D12
A13: ='Crosswalk_BEA_to_ISIC'!A19 | B13: ='Crosswalk_BEA_to_ISIC'!C19 | C13: ='Crosswalk_BEA_to_ISIC'!E19 | D13: =IFERROR(INDEX('1_Source_IndustryOutput'!$B$2:$B$72, MATCH($A13, '1_Source_IndustryOutput'!$A$2:$A$72, 0)), 0) | E13: =C13*D13
A14: ='Crosswalk_BEA_to_ISIC'!A20 | B14: ='Crosswalk_BEA_to_ISIC'!C20 | C14: ='Crosswalk_BEA_to_ISIC'!E20 | D14: =IFERROR(INDEX('1_Source_IndustryOutput'!$B$2:$B$72, MATCH($A14, '1_Source_IndustryOutput'!$A$2:$A$72, 0)), 0) | E14: =C14*D14
... A81: ='Crosswalk_BEA_to_ISIC'!A87 | B81: ='Crosswalk_BEA_to_ISIC'!C87 | C81: ='Crosswalk_BEA_to_ISIC'!E87 | D81: =IFERROR(INDEX('1_Source_IndustryOutput'!$B$2:$B$72, MATCH($A81, '1_Source_IndustryOutput'!$A$2:$A$72, 0)), 0) | E81: =C81*D81
A83: STEP 2 - aggregate weighted values to 42 ISIC, then deflate to 2012 USD (Keys!$C$2)
A84: ISIC_code | B84: aggregated_nominal | C84: value_2012USD
A85: 01T03 | B85: =SUMIFS('5_Calc_ISIC_aggregation'!$E$3:$E$81, '5_Calc_ISIC_aggregation'!$B$3:$B$81, $A85) | C85: =B85/Keys!$C$2
A86: 05 | B86: =SUMIFS('5_Calc_ISIC_aggregation'!$E$3:$E$81, '5_Calc_ISIC_aggregation'!$B$3:$B$81, $A86) | C86: =B86/Keys!$C$2
A87: 06 | B87: =SUMIFS('5_Calc_ISIC_aggregation'!$E$3:$E$81, '5_Calc_ISIC_aggregation'!$B$3:$B$81, $A87) | C87: =B87/Keys!$C$2
A88: 07T08 | B88: =SUMIFS('5_Calc_ISIC_aggregation'!$E$3:$E$81, '5_Calc_ISIC_aggregation'!$B$3:$B$81, $A88) | C88: =B88/Keys!$C$2
A89: 09 | B89: =SUMIFS('5_Calc_ISIC_aggregation'!$E$3:$E$81, '5_Calc_ISIC_aggregation'!$B$3:$B$81, $A89) | C89: =B89/Keys!$C$2
A90: 10T12 | B90: =SUMIFS('5_Calc_ISIC_aggregation'!$E$3:$E$81, '5_Calc_ISIC_aggregation'!$B$3:$B$81, $A90) | C90: =B90/Keys!$C$2
A91: 13T15 | B91: =SUMIFS('5_Calc_ISIC_aggregation'!$E$3:$E$81, '5_Calc_ISIC_aggregation'!$B$3:$B$81, $A91) | C91: =B91/Keys!$C$2
A92: 16 | B92: =SUMIFS('5_Calc_ISIC_aggregation'!$E$3:$E$81, '5_Calc_ISIC_aggregation'!$B$3:$B$81, $A92) | C92: =B92/Keys!$C$2
A93: 17T18 | B93: =SUMIFS('5_Calc_ISIC_aggregation'!$E$3:$E$81, '5_Calc_ISIC_aggregation'!$B$3:$B$81, $A93) | C93: =B93/Keys!$C$2
A94: 19 | B94: =SUMIFS('5_Calc_ISIC_aggregation'!$E$3:$E$81, '5_Calc_ISIC_aggregation'!$B$3:$B$81, $A94) | C94: =B94/Keys!$C$2
A95: 20 | B95: =SUMIFS('5_Calc_ISIC_aggregation'!$E$3:$E$81, '5_Calc_ISIC_aggregation'!$B$3:$B$81, $A95) | C95: =B95/Keys!$C$2
A96: 21 | B96: =SUMIFS('5_Calc_ISIC_aggregation'!$E$3:$E$81, '5_Calc_ISIC_aggregation'!$B$3:$B$81, $A96) | C96: =B96/Keys!$C$2
... A126: 97T98 | B126: =SUMIFS('5_Calc_ISIC_aggregation'!$E$3:$E$81, '5_Calc_ISIC_aggregation'!$B$3:$B$81, $A126) | C126: =B126/Keys!$C$2

Sheet BObIC
A1: Unit: USD | B1: 01T03 | C1: 05 | D1: 06 | E1: 07T08 | F1: 09 | G1: 10T12 | H1: 13T15 | I1: 16 | J1: 17T18 | K1: 19 | L1: 20 | M1: 21 | N1: 22 | O1: 231 | P1: 239 | Q1: 241 | R1: 242 | S1: 25 | T1: 26 | U1: 27 | V1: 28 | W1: 29 | X1: 30 | Y1: 31T33 | Z1: 351 | AA1: 352T353 | AB1: 36T39 | AC1: 41T43 | AD1: 45T47 | AE1: 49T53 | AF1: 55T56 | AG1: 58T60 | AH1: 61 | AI1: 62T63 | AJ1: 64T66 | AK1: 68 | AL1: 69T82 | AM1: 84 | AN1: 85 | AO1: 86T88 | AP1: 90T96 | AQ1: 97T98
A2: Output | B2: =INDEX('5_Calc_ISIC_aggregation'!$C$85:$C$126, MATCH(B$1, '5_Calc_ISIC_aggregation'!$A$85:$A$126, 0)) | C2: =INDEX('5_Calc_ISIC_aggregation'!$C$85:$C$126, MATCH(C$1, '5_Calc_ISIC_aggregation'!$A$85:$A$126, 0)) | D2: =INDEX('5_Calc_ISIC_aggregation'!$C$85:$C$126, MATCH(D$1, '5_Calc_ISIC_aggregation'!$A$85:$A$126, 0)) | E2: =INDEX('5_Calc_ISIC_aggregation'!$C$85:$C$126, MATCH(E$1, '5_Calc_ISIC_aggregation'!$A$85:$A$126, 0)) | F2: =INDEX('5_Calc_ISIC_aggregation'!$C$85:$C$126, MATCH(F$1, '5_Calc_ISIC_aggregation'!$A$85:$A$126, 0)) | G2: =INDEX('5_Calc_ISIC_aggregation'!$C$85:$C$126, MATCH(G$1, '5_Calc_ISIC_aggregation'!$A$85:$A$126, 0)) | H2: =INDEX('5_Calc_ISIC_aggregation'!$C$85:$C$126, MATCH(H$1, '5_Calc_ISIC_aggregation'!$A$85:$A$126, 0)) | I2: =INDEX('5_Calc_ISIC_aggregation'!$C$85:$C$126, MATCH(I$1, '5_Calc_ISIC_aggregation'!$A$85:$A$126, 0)) | ... AQ2: =INDEX('5_Calc_ISIC_aggregation'!$C$85:$C$126, MATCH(AQ$1, '5_Calc_ISIC_aggregation'!$A$85:$A$126, 0))
