Workbook

Sheet About
A1: Active state name: | B1: Oklahoma | C1: <- Change this state name (e.g., "California", "Texas") to switch the TTS-* views | E1: state_name | F1: state_abbr
A2: Active state code: | B2: =INDEX(Geography!$A$2:$A$49,MATCH($B$1,Geography!$B$2:$B$49,0)) -> OK | E2: Alabama | F2: AL
E3: Arkansas | F3: AR
A4: TTS Transportation Technology Shareweights -- per-state ZEV anchors | E4: Arizona | F4: AZ
A5: Built 2026-09-04 by outputs/TTS/_build_tts_workbook.py | E5: California | F5: CA
A6: US template: eps-us InputData/trans/TTS/Transportation Technology Shareweights.xlsx @ 05516d3e 2026-09-04 Updated TTS calibration to use AEO 2026 and assign TTS values to CNG/LPG vehicle types | E6: Colorado | F6: CO
E7: Connecticut | F7: CT
A8: *** PROVISIONAL: Costs_BAU holds US placeholder costs, not state costs. Do not deploy to state-eps-data until the per-state BAU cost export replaces them. *** | E8: Delaware | F8: DE
E9: Florida | F9: FL
A10: What this file is | E10: Georgia | F10: GA
A11: TTS is the multiplicative preference weight in the modified-logit allocation of new vehicle | E11: Iowa | F11: IA
A12: sales: New Vehicles_j is proportional to TTS_j * EXP(TTLE * CostPerMile_j). It is NOT a cap, | E12: Idaho | F12: ID
A13: despite the "Max Fraction of Production" header the EPS CSVs carry. You cannot write a | E13: Illinois | F13: IL
A14: target sales share into it -- you solve for the weight that reproduces an observed share | E14: Indiana | F14: IN
A15: given that state's costs. | E15: Kansas | F15: KS
E16: Kentucky | F16: KY
A17: All 48 EPS-modelled states are solved on the Solve tab simultaneously. About!B1 selects | E17: Louisiana | F17: LA
A18: which state the 12 TTS-* view tabs export. | E18: Massachusetts | F18: MA
E19: Maryland | F19: MD
A20: What is customized per state (locked with Olivia 2026-07-30) | E20: Maine | F20: ME
A21: 1. Base year 2025 only. State models have INITIAL TIME = 2025 (plcy-schd/IT/IT.csv), so | E21: Michigan | F21: MI
A22: the 2024 column sits before the simulation start and is carried over from the US file. | E22: Minnesota | F22: MN
A23: 2. ZEV technologies only: battery electric, plugin hybrid, hydrogen. | E23: Missouri | F23: MO
A24: 3. Fossil shareweights (gasoline, diesel, natural gas, LPG) are FROZEN at US values. | E24: Mississippi | F24: MS
A25: In a logit this means the fossil technologies split the residual (1 - ZEV share) in | E25: Montana | F25: MT
A26: proportion to their existing weights, so the national relative gasoline/diesel/NGV | E26: North Carolina | F26: NC
A27: preference carries through untouched and gasoline stays the numeraire at 1.0. | E27: North Dakota | F27: ND
A28: 4. 2050 endpoints and s-curve L/k/Xo stay national -- states differ only in their 2025 | E28: Nebraska | F28: NE
A29: anchor. Consequence to accept: every state converges to the same 2050 weight, so this | E29: New Hampshire | F29: NH
A30: customization moves the near and mid term, not 2050. | E30: New Jersey | F30: NJ
A31: 5. One formula change: Data!F14, the PHEV 2050 endpoint, is repointed from the 2024 | E31: New Mexico | F31: NM
... A35: mix, with an IFERROR guard for states that have no passenger rail (0/0 in the US form). | E35: Oklahoma | F35: OK
E36: Oregon | F36: OR
A37: Not customized: passenger HDV, freight LDV, freight HDV (the Alliance source is | E37: Pennsylvania | F37: PA
A38: light-duty only -- there is no state ZEV *sales* series for buses or trucks); aircraft, | E38: Rhode Island | F38: RI
A39: ships, freight rail and freight motorbikes are single-technology groups. | E39: South Carolina | F39: SC
E40: South Dakota | F40: SD
A41: Sources | E41: Tennessee | F41: TN
A42: Observed ZEV sales shares: Alliance for Automotive Innovation, "Get Connected: EV | E42: Texas | F42: TX
A43: Quarterly Report" Q4 2025 p.15 -- 2025 full-year new light-duty vehicle registrations by | E43: Utah | F43: UT
...

Sheet Geography
A1: state_abbr | B1: state_name
A2: AL | B2: Alabama
A3: AR | B3: Arkansas
A4: AZ | B4: Arizona
A5: CA | B5: California
A6: CO | B6: Colorado
A7: CT | B7: Connecticut
A8: DE | B8: Delaware
A9: FL | B9: Florida
A10: GA | B10: Georgia
A11: IA | B11: Iowa
A12: ID | B12: Idaho
... A49: WY | B49: Wyoming

Sheet Keys
A1: category | B1: key | C1: value | D1: description
A2: year | B2: base_year | C2: 2025 | D2: the only year solved; state models have INITIAL TIME = 2025, so the 2024 TTS column is before the simulation start and is inert
A3: unit | B3: pct_to_frac | C3: 0.01 | D3: the Alliance table is embedded verbatim in published percent; multiply to get a fraction
A4: logit | B4: ttle_ldv_psgr | C4: -8 | D4: TTLE logit exponent, passenger LDVs (trans/TTLE/TTLE.csv). Identical in all 48 states
A5: logit | B5: cost_cutoff | C5: 10 | D5: $/mile above which a technology is treated as unavailable (weight 0); matches COST_CUTOFF in the eps-us transport_calibration.py solver
A6: frozen_w | B6: w_gasoline | C6: 1 | D6: FROZEN US shareweight, gasoline, 2025 -- the logit numeraire (max weight = 1)
A7: frozen_w | B7: w_diesel | C7: 0.067938858 | D7: FROZEN US shareweight, diesel, 2025
A8: frozen_w | B8: w_NGV | C8: 0.00010673201 | D8: FROZEN US shareweight, natural gas, 2025
A9: frozen_w | B9: w_LPG | C9: 0 | D9: FROZEN US shareweight, LPG, 2025 (0 -- US cost/mile is in the thousands of $/mile, far above cost_cutoff)
A10: label | B10: tech_bev | C10: battery electric vehicle | D10: EPS Vehicle Technology label
A11: label | B11: tech_phev | C11: plugin hybrid vehicle | D11: EPS Vehicle Technology label
A12: label | B12: tech_h2 | C12: hydrogen vehicle | D12: EPS Vehicle Technology label
A13: label | B13: us_row | C13: U.S. | D13: row label of the national row on the Alliance_2025 tab
A14: qc | B14: share_tol | C14: 1e-06 | D14: max acceptable |realized - target| ZEV share on the Solve tab forward check
A15: qc | B15: w_max | C15: 1 | D15: shareweights must not exceed this: gasoline is the numeraire at 1 and the BEV 2050 endpoint is 1, so a 2025 anchor above it would invert the s-curve
A16: us_cost | B16: uscost_BEV | C16: 0.659046 | D16: US 2025 passenger-LDV cost per mile, BEV (eps-us calibration_parameters.csv) -- placeholder source for Costs_BAU
A17: us_cost | B17: uscost_NGV | C17: 0.547139 | D17: US 2025 passenger-LDV cost per mile, NGV (eps-us calibration_parameters.csv) -- placeholder source for Costs_BAU
A18: us_cost | B18: uscost_gasoline | C18: 0.512168 | D18: US 2025 passenger-LDV cost per mile, gasoline (eps-us calibration_parameters.csv) -- placeholder source for Costs_BAU
A19: us_cost | B19: uscost_diesel | C19: 0.578577 | D19: US 2025 passenger-LDV cost per mile, diesel (eps-us calibration_parameters.csv) -- placeholder source for Costs_BAU
A20: us_cost | B20: uscost_PHEV | C20: 0.527845 | D20: US 2025 passenger-LDV cost per mile, PHEV (eps-us calibration_parameters.csv) -- placeholder source for Costs_BAU
A21: us_cost | B21: uscost_LPG | C21: 9488.69 | D21: US 2025 passenger-LDV cost per mile, LPG (eps-us calibration_parameters.csv) -- placeholder source for Costs_BAU
A22: us_cost | B22: uscost_H2 | C22: 0.639724 | D22: US 2025 passenger-LDV cost per mile, H2 (eps-us calibration_parameters.csv) -- placeholder source for Costs_BAU

Sheet Alliance_2025
A1: Alliance for Automotive Innovation, "Get Connected: EV Quarterly Report" Q4 2025, p.15 -- 2025 (Full Year) New Light-Duty Vehicle Registrations By Powertrain
A2: Source: figures compiled by the Alliance with new registrations for retail and fleet data provided by S&P Global Mobility, January 1 - December 31, 2025. Embedded VERBATIM in published percent; cols G-I convert to fractions via Keys!pct_to_frac.
A4: state | B4: PHEV % | C4: BEV % | D4: FCEV % | E4: EV total % | G4: PHEV frac | H4: BEV frac | I4: H2 frac | J4: sum check
A5: AK | B5: 0.63 | C5: 2.5 | D5: 0 | E5: 3.13 | G5: =B5*Keys!$C$3 -> 0.0063 | H5: =C5*Keys!$C$3 -> 0.025 | I5: =D5*Keys!$C$3 -> 0 | J5: =B5+C5+D5-E5 -> 0
A6: AL | B6: 0.58 | C6: 3.04 | D6: 0 | E6: 3.62 | G6: =B6*Keys!$C$3 -> 0.0058 | H6: =C6*Keys!$C$3 -> 0.0304 | I6: =D6*Keys!$C$3 -> 0 | J6: =B6+C6+D6-E6 -> 0
A7: AR | B7: 0.54 | C7: 2.03 | D7: 0 | E7: 2.57 | G7: =B7*Keys!$C$3 -> 0.0054 | H7: =C7*Keys!$C$3 -> 0.0203 | I7: =D7*Keys!$C$3 -> 0 | J7: =B7+C7+D7-E7 -> 0
A8: AZ | B8: 1.18 | C8: 7.59 | D8: 0 | E8: 8.77 | G8: =B8*Keys!$C$3 -> 0.0118 | H8: =C8*Keys!$C$3 -> 0.0759 | I8: =D8*Keys!$C$3 -> 0 | J8: =B8+C8+D8-E8 -> 0
A9: CA | B9: 3.42 | C9: 20.42 | D9: 0.02 | E9: 23.86 | G9: =B9*Keys!$C$3 -> 0.0342 | H9: =C9*Keys!$C$3 -> 0.2042 | I9: =D9*Keys!$C$3 -> 0.0002 | J9: =B9+C9+D9-E9 -> 0
A10: CO | B10: 4.23 | C10: 15.62 | D10: 0 | E10: 19.85 | G10: =B10*Keys!$C$3 -> 0.0423 | H10: =C10*Keys!$C$3 -> 0.1562 | I10: =D10*Keys!$C$3 -> 0 | J10: =B10+C10+D10-E10 -> 0
A11: CT | B11: 2.88 | C11: 7.54 | D11: 0 | E11: 10.42 | G11: =B11*Keys!$C$3 -> 0.0288 | H11: =C11*Keys!$C$3 -> 0.0754 | I11: =D11*Keys!$C$3 -> 0 | J11: =B11+C11+D11-E11 -> 0
A12: DC | B12: 4.29 | C12: 14.7 | D12: 0 | E12: 18.98 | G12: =B12*Keys!$C$3 -> 0.0429 | H12: =C12*Keys!$C$3 -> 0.147 | I12: =D12*Keys!$C$3 -> 0 | J12: =B12+C12+D12-E12 -> 0.01
A13: DE | B13: 2.02 | C13: 7.23 | D13: 0 | E13: 9.26 | G13: =B13*Keys!$C$3 -> 0.0202 | H13: =C13*Keys!$C$3 -> 0.0723 | I13: =D13*Keys!$C$3 -> 0 | J13: =B13+C13+D13-E13 -> -0.01
A14: FL | B14: 1.35 | C14: 8.58 | D14: 0 | E14: 9.93 | G14: =B14*Keys!$C$3 -> 0.0135 | H14: =C14*Keys!$C$3 -> 0.0858 | I14: =D14*Keys!$C$3 -> 0 | J14: =B14+C14+D14-E14 -> 0
A15: GA | B15: 1.07 | C15: 7.63 | D15: 0 | E15: 8.7 | G15: =B15*Keys!$C$3 -> 0.0107 | H15: =C15*Keys!$C$3 -> 0.0763 | I15: =D15*Keys!$C$3 -> 0 | J15: =B15+C15+D15-E15 -> 0
A16: HI | B16: 1.52 | C16: 9.28 | D16: 0 | E16: 10.8 | G16: =B16*Keys!$C$3 -> 0.0152 | H16: =C16*Keys!$C$3 -> 0.0928 | I16: =D16*Keys!$C$3 -> 0 | J16: =B16+C16+D16-E16 -> 0
... A56: U.S. | B56: 1.72 | C56: 7.87 | D56: 0 | E56: 9.59 | G56: =B56*Keys!$C$3 -> 0.0172 | H56: =C56*Keys!$C$3 -> 0.0787 | I56: =D56*Keys!$C$3 -> 0 | J56: =B56+C56+D56-E56 -> 0

Sheet Costs_raw
A1: "BAU New Vehicle Cost per Mile" [LDVs,passenger,*], 2025, $/mile (2012 USD) -- embedded VERBATIM from the per-state BAU exports
A2: Source: state-eps-code/run-all/<ST>/BAU.tsv, first data column (= 2025). The standard run-all sweep already exports this variable, so no extra Vensim time is needed -- just rebuild after a sweep. (Verified identical to a dedicated export across CA/FL/ND/NY/TX, 2026-07-30.) TTSCOST.tsv from outputs/TTS/_export_bau_costs.py is the fallback for states a sweep has not covered; the source file is recorded per row.
A4: state_abbr | B4: BEV | C4: NGV | D4: gasoline | E4: diesel | F4: PHEV | G4: LPG | H4: H2 | I4: source file
A5: AL | B5: 0.546959 | C5: 0.436695 | D5: 0.407772 | E5: 0.466534 | F5: 0.428644 | G5: 7573.32 | H5: 0.524192 | I5: BAU.tsv
A6: AR | B6: 0.689851 | C6: 0.557837 | D6: 0.513717 | E6: 0.587663 | F6: 0.536695 | G6: 9674.21 | H6: 0.661737 | I6: BAU.tsv
A7: AZ | B7: 0.675449 | C7: 0.551364 | D7: 0.515567 | E7: 0.583551 | F7: 0.53654 | G7: 9561.96 | H7: 0.654388 | I7: BAU.tsv
A8: CA | B8: 0.715248 | C8: 0.578645 | D8: 0.536478 | E8: 0.61536 | F8: 0.587747 | G8: 10035.1 | H8: 0.685363 | I8: BAU.tsv
A9: CO | B9: 0.659681 | C9: 0.561807 | D9: 0.511724 | E9: 0.586671 | F9: 0.520398 | G9: 9743.05 | H9: 0.64193 | I9: BAU.tsv
A10: CT | B10: 0.582656 | C10: 0.468137 | D10: 0.431564 | E10: 0.497425 | F10: 0.475851 | G10: 8118.6 | H10: 0.557166 | I10: BAU.tsv
A11: DE | B11: 0.583769 | C11: 0.486529 | D11: 0.447214 | E11: 0.513531 | F11: 0.471471 | G11: 8437.56 | H11: 0.565734 | I11: BAU.tsv
A12: FL | B12: 0.642729 | C12: 0.523941 | D12: 0.485558 | E12: 0.556915 | F12: 0.508594 | G12: 9086.37 | H12: 0.623252 | I12: BAU.tsv
A13: GA | B13: 0.590461 | C13: 0.477947 | D13: 0.444317 | E13: 0.509483 | F13: 0.465724 | G13: 8288.72 | H13: 0.57103 | I13: BAU.tsv
A14: IA | B14: 0.776697 | C14: 0.628401 | D14: 0.576979 | E14: 0.660219 | F14: 0.603519 | G14: 10898 | H14: 0.741856 | I14: BAU.tsv
A15: ID | B15: 0.827244 | C15: 0.673521 | D15: 0.61828 | E15: 0.706378 | F15: 0.64332 | G15: 11680.4 | H15: 0.793085 | I15: BAU.tsv
A16: IL | B16: 0.773684 | C16: 0.641556 | D16: 0.589021 | E16: 0.675849 | F16: 0.619183 | G16: 11126.1 | H16: 0.740926 | I16: BAU.tsv
... A52: WY | B52: 0.76384 | C52: 0.620633 | D52: 0.570155 | E52: 0.651823 | F52: 0.595145 | G52: 10763.2 | H52: 0.733036 | I52: BAU.tsv

Sheet Costs_BAU
A1: BAU New Vehicle Cost per Mile -- passenger LDV, 2025 ($/mile, 2012 USD)
A2: All 48 states carry a real per-state BAU export (Costs_raw). No placeholders remain.
A4: state_abbr | B4: state_name | C4: BEV | D4: NGV | E4: gasoline | F4: diesel | G4: PHEV | H4: LPG | I4: H2 | J4: source
A5: AL | B5: Alabama | C5: =INDEX(Costs_raw!$B$5:$B$52,MATCH($A5,Costs_raw!$A$5:$A$52,0)) -> 0.546959 | D5: =INDEX(Costs_raw!$C$5:$C$52,MATCH($A5,Costs_raw!$A$5:$A$52,0)) -> 0.436695 | E5: =INDEX(Costs_raw!$D$5:$D$52,MATCH($A5,Costs_raw!$A$5:$A$52,0)) -> 0.407772 | F5: =INDEX(Costs_raw!$E$5:$E$52,MATCH($A5,Costs_raw!$A$5:$A$52,0)) -> 0.466534 | G5: =INDEX(Costs_raw!$F$5:$F$52,MATCH($A5,Costs_raw!$A$5:$A$52,0)) -> 0.428644 | H5: =INDEX(Costs_raw!$G$5:$G$52,MATCH($A5,Costs_raw!$A$5:$A$52,0)) -> 7573.32 | I5: =INDEX(Costs_raw!$H$5:$H$52,MATCH($A5,Costs_raw!$A$5:$A$52,0)) -> 0.524192 | J5: state BAU export
A6: AR | B6: Arkansas | C6: =INDEX(Costs_raw!$B$5:$B$52,MATCH($A6,Costs_raw!$A$5:$A$52,0)) -> 0.689851 | D6: =INDEX(Costs_raw!$C$5:$C$52,MATCH($A6,Costs_raw!$A$5:$A$52,0)) -> 0.557837 | E6: =INDEX(Costs_raw!$D$5:$D$52,MATCH($A6,Costs_raw!$A$5:$A$52,0)) -> 0.513717 | F6: =INDEX(Costs_raw!$E$5:$E$52,MATCH($A6,Costs_raw!$A$5:$A$52,0)) -> 0.587663 | G6: =INDEX(Costs_raw!$F$5:$F$52,MATCH($A6,Costs_raw!$A$5:$A$52,0)) -> 0.536695 | H6: =INDEX(Costs_raw!$G$5:$G$52,MATCH($A6,Costs_raw!$A$5:$A$52,0)) -> 9674.21 | I6: =INDEX(Costs_raw!$H$5:$H$52,MATCH($A6,Costs_raw!$A$5:$A$52,0)) -> 0.661737 | J6: state BAU export
A7: AZ | B7: Arizona | C7: =INDEX(Costs_raw!$B$5:$B$52,MATCH($A7,Costs_raw!$A$5:$A$52,0)) -> 0.675449 | D7: =INDEX(Costs_raw!$C$5:$C$52,MATCH($A7,Costs_raw!$A$5:$A$52,0)) -> 0.551364 | E7: =INDEX(Costs_raw!$D$5:$D$52,MATCH($A7,Costs_raw!$A$5:$A$52,0)) -> 0.515567 | F7: =INDEX(Costs_raw!$E$5:$E$52,MATCH($A7,Costs_raw!$A$5:$A$52,0)) -> 0.583551 | G7: =INDEX(Costs_raw!$F$5:$F$52,MATCH($A7,Costs_raw!$A$5:$A$52,0)) -> 0.53654 | H7: =INDEX(Costs_raw!$G$5:$G$52,MATCH($A7,Costs_raw!$A$5:$A$52,0)) -> 9561.96 | I7: =INDEX(Costs_raw!$H$5:$H$52,MATCH($A7,Costs_raw!$A$5:$A$52,0)) -> 0.654388 | J7: state BAU export
A8: CA | B8: California | C8: =INDEX(Costs_raw!$B$5:$B$52,MATCH($A8,Costs_raw!$A$5:$A$52,0)) -> 0.715248 | D8: =INDEX(Costs_raw!$C$5:$C$52,MATCH($A8,Costs_raw!$A$5:$A$52,0)) -> 0.578645 | E8: =INDEX(Costs_raw!$D$5:$D$52,MATCH($A8,Costs_raw!$A$5:$A$52,0)) -> 0.536478 | F8: =INDEX(Costs_raw!$E$5:$E$52,MATCH($A8,Costs_raw!$A$5:$A$52,0)) -> 0.61536 | G8: =INDEX(Costs_raw!$F$5:$F$52,MATCH($A8,Costs_raw!$A$5:$A$52,0)) -> 0.587747 | H8: =INDEX(Costs_raw!$G$5:$G$52,MATCH($A8,Costs_raw!$A$5:$A$52,0)) -> 10035.1 | I8: =INDEX(Costs_raw!$H$5:$H$52,MATCH($A8,Costs_raw!$A$5:$A$52,0)) -> 0.685363 | J8: state BAU export
A9: CO | B9: Colorado | C9: =INDEX(Costs_raw!$B$5:$B$52,MATCH($A9,Costs_raw!$A$5:$A$52,0)) -> 0.659681 | D9: =INDEX(Costs_raw!$C$5:$C$52,MATCH($A9,Costs_raw!$A$5:$A$52,0)) -> 0.561807 | E9: =INDEX(Costs_raw!$D$5:$D$52,MATCH($A9,Costs_raw!$A$5:$A$52,0)) -> 0.511724 | F9: =INDEX(Costs_raw!$E$5:$E$52,MATCH($A9,Costs_raw!$A$5:$A$52,0)) -> 0.586671 | G9: =INDEX(Costs_raw!$F$5:$F$52,MATCH($A9,Costs_raw!$A$5:$A$52,0)) -> 0.520398 | H9: =INDEX(Costs_raw!$G$5:$G$52,MATCH($A9,Costs_raw!$A$5:$A$52,0)) -> 9743.05 | I9: =INDEX(Costs_raw!$H$5:$H$52,MATCH($A9,Costs_raw!$A$5:$A$52,0)) -> 0.64193 | J9: state BAU export
A10: CT | B10: Connecticut | C10: =INDEX(Costs_raw!$B$5:$B$52,MATCH($A10,Costs_raw!$A$5:$A$52,0)) -> 0.582656 | D10: =INDEX(Costs_raw!$C$5:$C$52,MATCH($A10,Costs_raw!$A$5:$A$52,0)) -> 0.468137 | E10: =INDEX(Costs_raw!$D$5:$D$52,MATCH($A10,Costs_raw!$A$5:$A$52,0)) -> 0.431564 | F10: =INDEX(Costs_raw!$E$5:$E$52,MATCH($A10,Costs_raw!$A$5:$A$52,0)) -> 0.497425 | G10: =INDEX(Costs_raw!$F$5:$F$52,MATCH($A10,Costs_raw!$A$5:$A$52,0)) -> 0.475851 | H10: =INDEX(Costs_raw!$G$5:$G$52,MATCH($A10,Costs_raw!$A$5:$A$52,0)) -> 8118.6 | I10: =INDEX(Costs_raw!$H$5:$H$52,MATCH($A10,Costs_raw!$A$5:$A$52,0)) -> 0.557166 | J10: state BAU export
A11: DE | B11: Delaware | C11: =INDEX(Costs_raw!$B$5:$B$52,MATCH($A11,Costs_raw!$A$5:$A$52,0)) -> 0.583769 | D11: =INDEX(Costs_raw!$C$5:$C$52,MATCH($A11,Costs_raw!$A$5:$A$52,0)) -> 0.486529 | E11: =INDEX(Costs_raw!$D$5:$D$52,MATCH($A11,Costs_raw!$A$5:$A$52,0)) -> 0.447214 | F11: =INDEX(Costs_raw!$E$5:$E$52,MATCH($A11,Costs_raw!$A$5:$A$52,0)) -> 0.513531 | G11: =INDEX(Costs_raw!$F$5:$F$52,MATCH($A11,Costs_raw!$A$5:$A$52,0)) -> 0.471471 | H11: =INDEX(Costs_raw!$G$5:$G$52,MATCH($A11,Costs_raw!$A$5:$A$52,0)) -> 8437.56 | I11: =INDEX(Costs_raw!$H$5:$H$52,MATCH($A11,Costs_raw!$A$5:$A$52,0)) -> 0.565734 | J11: state BAU export
A12: FL | B12: Florida | C12: =INDEX(Costs_raw!$B$5:$B$52,MATCH($A12,Costs_raw!$A$5:$A$52,0)) -> 0.642729 | D12: =INDEX(Costs_raw!$C$5:$C$52,MATCH($A12,Costs_raw!$A$5:$A$52,0)) -> 0.523941 | E12: =INDEX(Costs_raw!$D$5:$D$52,MATCH($A12,Costs_raw!$A$5:$A$52,0)) -> 0.485558 | F12: =INDEX(Costs_raw!$E$5:$E$52,MATCH($A12,Costs_raw!$A$5:$A$52,0)) -> 0.556915 | G12: =INDEX(Costs_raw!$F$5:$F$52,MATCH($A12,Costs_raw!$A$5:$A$52,0)) -> 0.508594 | H12: =INDEX(Costs_raw!$G$5:$G$52,MATCH($A12,Costs_raw!$A$5:$A$52,0)) -> 9086.37 | I12: =INDEX(Costs_raw!$H$5:$H$52,MATCH($A12,Costs_raw!$A$5:$A$52,0)) -> 0.623252 | J12: state BAU export
A13: GA | B13: Georgia | C13: =INDEX(Costs_raw!$B$5:$B$52,MATCH($A13,Costs_raw!$A$5:$A$52,0)) -> 0.590461 | D13: =INDEX(Costs_raw!$C$5:$C$52,MATCH($A13,Costs_raw!$A$5:$A$52,0)) -> 0.477947 | E13: =INDEX(Costs_raw!$D$5:$D$52,MATCH($A13,Costs_raw!$A$5:$A$52,0)) -> 0.444317 | F13: =INDEX(Costs_raw!$E$5:$E$52,MATCH($A13,Costs_raw!$A$5:$A$52,0)) -> 0.509483 | G13: =INDEX(Costs_raw!$F$5:$F$52,MATCH($A13,Costs_raw!$A$5:$A$52,0)) -> 0.465724 | H13: =INDEX(Costs_raw!$G$5:$G$52,MATCH($A13,Costs_raw!$A$5:$A$52,0)) -> 8288.72 | I13: =INDEX(Costs_raw!$H$5:$H$52,MATCH($A13,Costs_raw!$A$5:$A$52,0)) -> 0.57103 | J13: state BAU export
A14: IA | B14: Iowa | C14: =INDEX(Costs_raw!$B$5:$B$52,MATCH($A14,Costs_raw!$A$5:$A$52,0)) -> 0.776697 | D14: =INDEX(Costs_raw!$C$5:$C$52,MATCH($A14,Costs_raw!$A$5:$A$52,0)) -> 0.628401 | E14: =INDEX(Costs_raw!$D$5:$D$52,MATCH($A14,Costs_raw!$A$5:$A$52,0)) -> 0.576979 | F14: =INDEX(Costs_raw!$E$5:$E$52,MATCH($A14,Costs_raw!$A$5:$A$52,0)) -> 0.660219 | G14: =INDEX(Costs_raw!$F$5:$F$52,MATCH($A14,Costs_raw!$A$5:$A$52,0)) -> 0.603519 | H14: =INDEX(Costs_raw!$G$5:$G$52,MATCH($A14,Costs_raw!$A$5:$A$52,0)) -> 10898 | I14: =INDEX(Costs_raw!$H$5:$H$52,MATCH($A14,Costs_raw!$A$5:$A$52,0)) -> 0.741856 | J14: state BAU export
A15: ID | B15: Idaho | C15: =INDEX(Costs_raw!$B$5:$B$52,MATCH($A15,Costs_raw!$A$5:$A$52,0)) -> 0.827244 | D15: =INDEX(Costs_raw!$C$5:$C$52,MATCH($A15,Costs_raw!$A$5:$A$52,0)) -> 0.673521 | E15: =INDEX(Costs_raw!$D$5:$D$52,MATCH($A15,Costs_raw!$A$5:$A$52,0)) -> 0.61828 | F15: =INDEX(Costs_raw!$E$5:$E$52,MATCH($A15,Costs_raw!$A$5:$A$52,0)) -> 0.706378 | G15: =INDEX(Costs_raw!$F$5:$F$52,MATCH($A15,Costs_raw!$A$5:$A$52,0)) -> 0.64332 | H15: =INDEX(Costs_raw!$G$5:$G$52,MATCH($A15,Costs_raw!$A$5:$A$52,0)) -> 11680.4 | I15: =INDEX(Costs_raw!$H$5:$H$52,MATCH($A15,Costs_raw!$A$5:$A$52,0)) -> 0.793085 | J15: state BAU export
A16: IL | B16: Illinois | C16: =INDEX(Costs_raw!$B$5:$B$52,MATCH($A16,Costs_raw!$A$5:$A$52,0)) -> 0.773684 | D16: =INDEX(Costs_raw!$C$5:$C$52,MATCH($A16,Costs_raw!$A$5:$A$52,0)) -> 0.641556 | E16: =INDEX(Costs_raw!$D$5:$D$52,MATCH($A16,Costs_raw!$A$5:$A$52,0)) -> 0.589021 | F16: =INDEX(Costs_raw!$E$5:$E$52,MATCH($A16,Costs_raw!$A$5:$A$52,0)) -> 0.675849 | G16: =INDEX(Costs_raw!$F$5:$F$52,MATCH($A16,Costs_raw!$A$5:$A$52,0)) -> 0.619183 | H16: =INDEX(Costs_raw!$G$5:$G$52,MATCH($A16,Costs_raw!$A$5:$A$52,0)) -> 11126.1 | I16: =INDEX(Costs_raw!$H$5:$H$52,MATCH($A16,Costs_raw!$A$5:$A$52,0)) -> 0.740926 | J16: state BAU export
... A52: WY | B52: Wyoming | C52: =INDEX(Costs_raw!$B$5:$B$52,MATCH($A52,Costs_raw!$A$5:$A$52,0)) -> 0.76384 | D52: =INDEX(Costs_raw!$C$5:$C$52,MATCH($A52,Costs_raw!$A$5:$A$52,0)) -> 0.620633 | E52: =INDEX(Costs_raw!$D$5:$D$52,MATCH($A52,Costs_raw!$A$5:$A$52,0)) -> 0.570155 | F52: =INDEX(Costs_raw!$E$5:$E$52,MATCH($A52,Costs_raw!$A$5:$A$52,0)) -> 0.651823 | G52: =INDEX(Costs_raw!$F$5:$F$52,MATCH($A52,Costs_raw!$A$5:$A$52,0)) -> 0.595145 | H52: =INDEX(Costs_raw!$G$5:$G$52,MATCH($A52,Costs_raw!$A$5:$A$52,0)) -> 10763.2 | I52: =INDEX(Costs_raw!$H$5:$H$52,MATCH($A52,Costs_raw!$A$5:$A$52,0)) -> 0.733036 | J52: state BAU export

Sheet Solve
A1: ZEV shareweight solve -- passenger LDV, 2025, all 48 EPS-modelled states
A2: Closed form: F = SUM(frozen fossil w * EXP(b*c)); D = F/(1-S_Z); w_k = s_k*D*EXP(-b*c_k). Fossil weights are frozen (Keys!frozen_w_*), so the fossil technologies split the residual (1-S_Z) in proportion to their existing weights. Reproduces the shipped US file to 1.6e-8 when fed US shares+costs.
A3: Then RESCALE (col R-Y, Olivia 2026-07-30): divide all SEVEN weights by MAX(1, w_BEV, w_PHEV, w_H2) so the max weight is 1, per the US solver convention. The logit is scale-invariant, so this leaves every realized share EXACTLY unchanged (cols Z-AB verify that) -- it only stops a >1 anchor from inverting the 2025->2050 s-curve, whose BEV endpoint is 1. It is a no-op wherever w_BEV <= 1, and there gasoline stays at exactly 1.0. Where it does bite, the fossil RATIOS are still frozen -- only the common scale moves, which is the only scale-invariant reading of "freeze the fossil weights".
A5: state_abbr | B5: state_name | C5: target BEV share | D5: target PHEV share | E5: target H2 share | F5: S_Z (ZEV total) | G5: b (exponent) | I5: gasoline term | J5: diesel term | K5: NGV term | L5: LPG term | M5: F (fossil denom) | N5: D (full denom) | O5: w BEV raw | P5: w PHEV raw | Q5: w H2 raw | R5: scale = MAX(1,ZEV w) | S5: w BEV | T5: w PHEV | U5: w H2 | V5: w gasoline | W5: w diesel | X5: w NGV | Y5: w LPG | Z5: check BEV share | AA5: check PHEV share | AB5: check H2 share | AC5: max abs err | AD5: QC | AF5: tier (1..4, low->high) | AG5: log10 w BEV raw | AH5: log10 w PHEV raw | AI5: log10 w H2 raw | AJ5: TIER w BEV (geomean) | AK5: TIER w PHEV | AL5: TIER w H2 | AM5: tier scale = MAX(1,ZEV) | AN5: tiered w BEV | AO5: tiered w PHEV | AP5: tiered w H2 | AQ5: tiered w gasoline | AR5: tiered w diesel | AS5: tiered w NGV | AT5: tiered w LPG | AU5: implied BEV share | AV5: implied PHEV share | AW5: implied H2 share | AX5: implied ZEV total | AY5: ZEV err vs target (pp)
A6: AL | B6: Alabama | C6: =INDEX(Alliance_2025!$H$5:$H$56,MATCH($A6,Alliance_2025!$A$5:$A$56,0)) -> 0.0304 | D6: =INDEX(Alliance_2025!$G$5:$G$56,MATCH($A6,Alliance_2025!$A$5:$A$56,0)) -> 0.0058 | E6: =INDEX(Alliance_2025!$I$5:$I$56,MATCH($A6,Alliance_2025!$A$5:$A$56,0)) -> 0 | F6: =C6+D6+E6 -> 0.0362 | G6: =Keys!$C$4 -> -8 | I6: =IF(INDEX(Costs_BAU!$E$5:$E$52,MATCH($A6,Costs_BAU!$A$5:$A$52,0))>Keys!$C$5,0,Keys!$C$6*EXP($G6*INDEX(Costs_BAU!$E$5:$E$52,MATCH($A6,Costs_BAU!$A$5:$A$52,0)))) -> 0.038304956 | J6: =IF(INDEX(Costs_BAU!$F$5:$F$52,MATCH($A6,Costs_BAU!$A$5:$A$52,0))>Keys!$C$5,0,Keys!$C$7*EXP($G6*INDEX(Costs_BAU!$F$5:$F$52,MATCH($A6,Costs_BAU!$A$5:$A$52,0)))) -> 0.0016263466 | K6: =IF(INDEX(Costs_BAU!$D$5:$D$52,MATCH($A6,Costs_BAU!$A$5:$A$52,0))>Keys!$C$5,0,Keys!$C$8*EXP($G6*INDEX(Costs_BAU!$D$5:$D$52,MATCH($A6,Costs_BAU!$A$5:$A$52,0)))) -> 3.2438507e-06 | L6: =IF(INDEX(Costs_BAU!$H$5:$H$52,MATCH($A6,Costs_BAU!$A$5:$A$52,0))>Keys!$C$5,0,Keys!$C$9*EXP($G6*INDEX(Costs_BAU!$H$5:$H$52,MATCH($A6,Costs_BAU!$A$5:$A$52,0)))) -> 0 | M6: =SUM(I6:L6) -> 0.039934546 | N6: =M6/(1-F6) -> 0.041434474 | O6: =$C6*$N6*EXP(-$G6*INDEX(Costs_BAU!$C$5:$C$52,MATCH($A6,Costs_BAU!$A$5:$A$52,0))) -> 0.10013032 | P6: =$D6*$N6*EXP(-$G6*INDEX(Costs_BAU!$G$5:$G$52,MATCH($A6,Costs_BAU!$A$5:$A$52,0))) -> 0.0074139835 | Q6: =$E6*$N6*EXP(-$G6*INDEX(Costs_BAU!$I$5:$I$52,MATCH($A6,Costs_BAU!$A$5:$A$52,0))) -> 0 | R6: =MAX(Keys!$C$15,O6,P6,Q6) -> 1 | S6: =O6/$R6 -> 0.10013032 | T6: =P6/$R6 -> 0.0074139835 | U6: =Q6/$R6 -> 0 | V6: =Keys!$C$6/$R6 -> 1 | W6: =Keys!$C$7/$R6 -> 0.067938858 | X6: =Keys!$C$8/$R6 -> 0.00010673201 | Y6: =Keys!$C$9/$R6 -> 0 | Z6: =S6*EXP($G6*INDEX(Costs_BAU!$C$5:$C$52,MATCH($A6,Costs_BAU!$A$5:$A$52,0)))/(S6*EXP($G6*INDEX(Costs_BAU!$C$5:$C$52,MATCH($A6,Costs_BAU!$A$5:$A$52,0)))+T6*EXP($G6*INDEX(Costs_BAU!$G$5:$G$52,MATCH($A6,Costs_BAU!$A$5:$A$52,0)))+U6*EXP($G6*INDEX(Costs_BAU!$I$5:$I$52,MATCH($A6,Costs_BAU!$A$5:$A$52,0)))+V6*EXP($G6*INDEX(Costs_BAU!$E$5:$E$52,MATCH($A6,Costs_BAU!$A$5:$A$52,0)))+W6*EXP($G6*INDEX(Costs_BAU!$F$5:$F$52,MATCH($A6,Costs_BAU!$A$5:$A$52,0)))+X6*EXP($G6*INDEX(Costs_BAU!$D$5:$D$52,MATCH($A6,Costs_BAU!$A$5:$A$52,0)))+Y6*EXP($G6*INDEX(Costs_BAU!$H$5:$H$52,MATCH($A6,Costs_BAU!$A$5:$A$52,0)))) -> 0.0304 | AA6: =T6*EXP($G6*INDEX(Costs_BAU!$G$5:$G$52,MATCH($A6,Costs_BAU!$A$5:$A$52,0)))/(S6*EXP($G6*INDEX(Costs_BAU!$C$5:$C$52,MATCH($A6,Costs_BAU!$A$5:$A$52,0)))+T6*EXP($G6*INDEX(Costs_BAU!$G$5:$G$52,MATCH($A6,Costs_BAU!$A$5:$A$52,0)))+U6*EXP($G6*INDEX(Costs_BAU!$I$5:$I$52,MATCH($A6,Costs_BAU!$A$5:$A$52,0)))+V6*EXP($G6*INDEX(Costs_BAU!$E$5:$E$52,MATCH($A6,Costs_BAU!$A$5:$A$52,0)))+W6*EXP($G6*INDEX(Costs_BAU!$F$5:$F$52,MATCH($A6,Costs_BAU!$A$5:$A$52,0)))+X6*EXP($G6*INDEX(Costs_BAU!$D$5:$D$52,MATCH($A6,Costs_BAU!$A$5:$A$52,0)))+Y6*EXP($G6*INDEX(Costs_BAU!$H$5:$H$52,MATCH($A6,Costs_BAU!$A$5:$A$52,0)))) -> 0.0058 | AB6: =U6*EXP($G6*INDEX(Costs_BAU!$I$5:$I$52,MATCH($A6,Costs_BAU!$A$5:$A$52,0)))/(S6*EXP($G6*INDEX(Costs_BAU!$C$5:$C$52,MATCH($A6,Costs_BAU!$A$5:$A$52,0)))+T6*EXP($G6*INDEX(Costs_BAU!$G$5:$G$52,MATCH($A6,Costs_BAU!$A$5:$A$52,0)))+U6*EXP($G6*INDEX(Costs_BAU!$I$5:$I$52,MATCH($A6,Costs_BAU!$A$5:$A$52,0)))+V6*EXP($G6*INDEX(Costs_BAU!$E$5:$E$52,MATCH($A6,Costs_BAU!$A$5:$A$52,0)))+W6*EXP($G6*INDEX(Costs_BAU!$F$5:$F$52,MATCH($A6,Costs_BAU!$A$5:$A$52,0)))+X6*EXP($G6*INDEX(Costs_BAU!$D$5:$D$52,MATCH($A6,Costs_BAU!$A$5:$A$52,0)))+Y6*EXP($G6*INDEX(Costs_BAU!$H$5:$H$52,MATCH($A6,Costs_BAU!$A$5:$A$52,0)))) -> 0 | AC6: =MAX(ABS(Z6-C6),ABS(AA6-D6),ABS(AB6-E6)) -> 3.469447e-18 | AD6: =IF(AC6>Keys!$C$14,"SHARE MISMATCH",IF(ABS(MAX(S6:Y6)-Keys!$C$15)>Keys!$C$14,"MAX WEIGHT <> 1",IF(R6>Keys!$C$15,"ok (rescaled)","ok"))) -> ok | AF6: 1 | AG6: =IF(O6>0,LOG10(O6),"") -> -0.99943438 | AH6: =IF(P6>0,LOG10(P6),"") -> -2.1299484 | AI6: =IF(Q6>0,LOG10(Q6),"") | AJ6: =IFERROR(10^AVERAGEIF($AF$6:$AF$53,AF6,$AG$6:$AG$53),0) -> 0.093934898 | AK6: =IFERROR(10^AVERAGEIF($AF$6:$AF$53,AF6,$AH$6:$AH$53),0) -> 0.010021685 | AL6: =IFERROR(10^AVERAGEIF($AF$6:$AF$53,AF6,$AI$6:$AI$53),0) -> 0 | AM6: =MAX(1,AJ6,AK6,AL6) -> 1 | AN6: =AJ6/AM6 -> 0.093934898 | AO6: =AK6/AM6 -> 0.010021685 | AP6: =AL6/AM6 -> 0 | AQ6: =Keys!$C$6/AM6 -> 1 | AR6: =Keys!$C$7/AM6 -> 0.067938858 | AS6: =Keys!$C$8/AM6 -> 0.00010673201 | AT6: =Keys!$C$9/AM6 -> 0 | AU6: =AN6*EXP($G6*INDEX(Costs_BAU!$C$5:$C$52,MATCH($A6,Costs_BAU!$A$5:$A$52,0)))/(AN6*EXP($G6*INDEX(Costs_BAU!$C$5:$C$52,MATCH($A6,Costs_BAU!$A$5:$A$52,0)))+AO6*EXP($G6*INDEX(Costs_BAU!$G$5:$G$52,MATCH($A6,Costs_BAU!$A$5:$A$52,0)))+AP6*EXP($G6*INDEX(Costs_BAU!$I$5:$I$52,MATCH($A6,Costs_BAU!$A$5:$A$52,0)))+AQ6*EXP($G6*INDEX(Costs_BAU!$E$5:$E$52,MATCH($A6,Costs_BAU!$A$5:$A$52,0)))+AR6*EXP($G6*INDEX(Costs_BAU!$F$5:$F$52,MATCH($A6,Costs_BAU!$A$5:$A$52,0)))+AS6*EXP($G6*INDEX(Costs_BAU!$D$5:$D$52,MATCH($A6,Costs_BAU!$A$5:$A$52,0)))+AT6*EXP($G6*INDEX(Costs_BAU!$H$5:$H$52,MATCH($A6,Costs_BAU!$A$5:$A$52,0)))) -> 0.028514506 | AV6: =AO6*EXP($G6*INDEX(Costs_BAU!$G$5:$G$52,MATCH($A6,Costs_BAU!$A$5:$A$52,0)))/(AN6*EXP($G6*INDEX(Costs_BAU!$C$5:$C$52,MATCH($A6,Costs_BAU!$A$5:$A$52,0)))+AO6*EXP($G6*INDEX(Costs_BAU!$G$5:$G$52,MATCH($A6,Costs_BAU!$A$5:$A$52,0)))+AP6*EXP($G6*INDEX(Costs_BAU!$I$5:$I$52,MATCH($A6,Costs_BAU!$A$5:$A$52,0)))+AQ6*EXP($G6*INDEX(Costs_BAU!$E$5:$E$52,MATCH($A6,Costs_BAU!$A$5:$A$52,0)))+AR6*EXP($G6*INDEX(Costs_BAU!$F$5:$F$52,MATCH($A6,Costs_BAU!$A$5:$A$52,0)))+AS6*EXP($G6*INDEX(Costs_BAU!$D$5:$D$52,MATCH($A6,Costs_BAU!$A$5:$A$52,0)))+AT6*EXP($G6*INDEX(Costs_BAU!$H$5:$H$52,MATCH($A6,Costs_BAU!$A$5:$A$52,0)))) -> 0.0078387724 | AW6: =AP6*EXP($G6*INDEX(Costs_BAU!$I$5:$I$52,MATCH($A6,Costs_BAU!$A$5:$A$52,0)))/(AN6*EXP($G6*INDEX(Costs_BAU!$C$5:$C$52,MATCH($A6,Costs_BAU!$A$5:$A$52,0)))+AO6*EXP($G6*INDEX(Costs_BAU!$G$5:$G$52,MATCH($A6,Costs_BAU!$A$5:$A$52,0)))+AP6*EXP($G6*INDEX(Costs_BAU!$I$5:$I$52,MATCH($A6,Costs_BAU!$A$5:$A$52,0)))+AQ6*EXP($G6*INDEX(Costs_BAU!$E$5:$E$52,MATCH($A6,Costs_BAU!$A$5:$A$52,0)))+AR6*EXP($G6*INDEX(Costs_BAU!$F$5:$F$52,MATCH($A6,Costs_BAU!$A$5:$A$52,0)))+AS6*EXP($G6*INDEX(Costs_BAU!$D$5:$D$52,MATCH($A6,Costs_BAU!$A$5:$A$52,0)))+AT6*EXP($G6*INDEX(Costs_BAU!$H$5:$H$52,MATCH($A6,Costs_BAU!$A$5:$A$52,0)))) -> 0 | AX6: =AU6+AV6+AW6 -> 0.036353279 | AY6: =(AX6-$F6)*100 -> 0.015327887
A7: AR | B7: Arkansas | C7: =INDEX(Alliance_2025!$H$5:$H$56,MATCH($A7,Alliance_2025!$A$5:$A$56,0)) -> 0.0203 | D7: =INDEX(Alliance_2025!$G$5:$G$56,MATCH($A7,Alliance_2025!$A$5:$A$56,0)) -> 0.0054 | E7: =INDEX(Alliance_2025!$I$5:$I$56,MATCH($A7,Alliance_2025!$A$5:$A$56,0)) -> 0 | F7: =C7+D7+E7 -> 0.0257 | G7: =Keys!$C$4 -> -8 | I7: =IF(INDEX(Costs_BAU!$E$5:$E$52,MATCH($A7,Costs_BAU!$A$5:$A$52,0))>Keys!$C$5,0,Keys!$C$6*EXP($G7*INDEX(Costs_BAU!$E$5:$E$52,MATCH($A7,Costs_BAU!$A$5:$A$52,0)))) -> 0.016412107 | J7: =IF(INDEX(Costs_BAU!$F$5:$F$52,MATCH($A7,Costs_BAU!$A$5:$A$52,0))>Keys!$C$5,0,Keys!$C$7*EXP($G7*INDEX(Costs_BAU!$F$5:$F$52,MATCH($A7,Costs_BAU!$A$5:$A$52,0)))) -> 0.0006171175 | K7: =IF(INDEX(Costs_BAU!$D$5:$D$52,MATCH($A7,Costs_BAU!$A$5:$A$52,0))>Keys!$C$5,0,Keys!$C$8*EXP($G7*INDEX(Costs_BAU!$D$5:$D$52,MATCH($A7,Costs_BAU!$A$5:$A$52,0)))) -> 1.2307517e-06 | L7: =IF(INDEX(Costs_BAU!$H$5:$H$52,MATCH($A7,Costs_BAU!$A$5:$A$52,0))>Keys!$C$5,0,Keys!$C$9*EXP($G7*INDEX(Costs_BAU!$H$5:$H$52,MATCH($A7,Costs_BAU!$A$5:$A$52,0)))) -> 0 | M7: =SUM(I7:L7) -> 0.017030455 | N7: =M7/(1-F7) -> 0.017479683 | O7: =$C7*$N7*EXP(-$G7*INDEX(Costs_BAU!$C$5:$C$52,MATCH($A7,Costs_BAU!$A$5:$A$52,0))) -> 0.088474364 | P7: =$D7*$N7*EXP(-$G7*INDEX(Costs_BAU!$G$5:$G$52,MATCH($A7,Costs_BAU!$A$5:$A$52,0))) -> 0.0069118885 | Q7: =$E7*$N7*EXP(-$G7*INDEX(Costs_BAU!$I$5:$I$52,MATCH($A7,Costs_BAU!$A$5:$A$52,0))) -> 0 | R7: =MAX(Keys!$C$15,O7,P7,Q7) -> 1 | S7: =O7/$R7 -> 0.088474364 | T7: =P7/$R7 -> 0.0069118885 | U7: =Q7/$R7 -> 0 | V7: =Keys!$C$6/$R7 -> 1 | W7: =Keys!$C$7/$R7 -> 0.067938858 | X7: =Keys!$C$8/$R7 -> 0.00010673201 | Y7: =Keys!$C$9/$R7 -> 0 | Z7: =S7*EXP($G7*INDEX(Costs_BAU!$C$5:$C$52,MATCH($A7,Costs_BAU!$A$5:$A$52,0)))/(S7*EXP($G7*INDEX(Costs_BAU!$C$5:$C$52,MATCH($A7,Costs_BAU!$A$5:$A$52,0)))+T7*EXP($G7*INDEX(Costs_BAU!$G$5:$G$52,MATCH($A7,Costs_BAU!$A$5:$A$52,0)))+U7*EXP($G7*INDEX(Costs_BAU!$I$5:$I$52,MATCH($A7,Costs_BAU!$A$5:$A$52,0)))+V7*EXP($G7*INDEX(Costs_BAU!$E$5:$E$52,MATCH($A7,Costs_BAU!$A$5:$A$52,0)))+W7*EXP($G7*INDEX(Costs_BAU!$F$5:$F$52,MATCH($A7,Costs_BAU!$A$5:$A$52,0)))+X7*EXP($G7*INDEX(Costs_BAU!$D$5:$D$52,MATCH($A7,Costs_BAU!$A$5:$A$52,0)))+Y7*EXP($G7*INDEX(Costs_BAU!$H$5:$H$52,MATCH($A7,Costs_BAU!$A$5:$A$52,0)))) -> 0.0203 | AA7: =T7*EXP($G7*INDEX(Costs_BAU!$G$5:$G$52,MATCH($A7,Costs_BAU!$A$5:$A$52,0)))/(S7*EXP($G7*INDEX(Costs_BAU!$C$5:$C$52,MATCH($A7,Costs_BAU!$A$5:$A$52,0)))+T7*EXP($G7*INDEX(Costs_BAU!$G$5:$G$52,MATCH($A7,Costs_BAU!$A$5:$A$52,0)))+U7*EXP($G7*INDEX(Costs_BAU!$I$5:$I$52,MATCH($A7,Costs_BAU!$A$5:$A$52,0)))+V7*EXP($G7*INDEX(Costs_BAU!$E$5:$E$52,MATCH($A7,Costs_BAU!$A$5:$A$52,0)))+W7*EXP($G7*INDEX(Costs_BAU!$F$5:$F$52,MATCH($A7,Costs_BAU!$A$5:$A$52,0)))+X7*EXP($G7*INDEX(Costs_BAU!$D$5:$D$52,MATCH($A7,Costs_BAU!$A$5:$A$52,0)))+Y7*EXP($G7*INDEX(Costs_BAU!$H$5:$H$52,MATCH($A7,Costs_BAU!$A$5:$A$52,0)))) -> 0.0054 | AB7: =U7*EXP($G7*INDEX(Costs_BAU!$I$5:$I$52,MATCH($A7,Costs_BAU!$A$5:$A$52,0)))/(S7*EXP($G7*INDEX(Costs_BAU!$C$5:$C$52,MATCH($A7,Costs_BAU!$A$5:$A$52,0)))+T7*EXP($G7*INDEX(Costs_BAU!$G$5:$G$52,MATCH($A7,Costs_BAU!$A$5:$A$52,0)))+U7*EXP($G7*INDEX(Costs_BAU!$I$5:$I$52,MATCH($A7,Costs_BAU!$A$5:$A$52,0)))+V7*EXP($G7*INDEX(Costs_BAU!$E$5:$E$52,MATCH($A7,Costs_BAU!$A$5:$A$52,0)))+W7*EXP($G7*INDEX(Costs_BAU!$F$5:$F$52,MATCH($A7,Costs_BAU!$A$5:$A$52,0)))+X7*EXP($G7*INDEX(Costs_BAU!$D$5:$D$52,MATCH($A7,Costs_BAU!$A$5:$A$52,0)))+Y7*EXP($G7*INDEX(Costs_BAU!$H$5:$H$52,MATCH($A7,Costs_BAU!$A$5:$A$52,0)))) -> 0 | AC7: =MAX(ABS(Z7-C7),ABS(AA7-D7),ABS(AB7-E7)) -> 3.469447e-18 | AD7: =IF(AC7>Keys!$C$14,"SHARE MISMATCH",IF(ABS(MAX(S7:Y7)-Keys!$C$15)>Keys!$C$14,"MAX WEIGHT <> 1",IF(R7>Keys!$C$15,"ok (rescaled)","ok"))) -> ok | AF7: 1 | AG7: =IF(O7>0,LOG10(O7),"") -> -1.0531826 | AH7: =IF(P7>0,LOG10(P7),"") -> -2.1604033 | AI7: =IF(Q7>0,LOG10(Q7),"") | AJ7: =IFERROR(10^AVERAGEIF($AF$6:$AF$53,AF7,$AG$6:$AG$53),0) -> 0.093934898 | AK7: =IFERROR(10^AVERAGEIF($AF$6:$AF$53,AF7,$AH$6:$AH$53),0) -> 0.010021685 | AL7: =IFERROR(10^AVERAGEIF($AF$6:$AF$53,AF7,$AI$6:$AI$53),0) -> 0 | AM7: =MAX(1,AJ7,AK7,AL7) -> 1 | AN7: =AJ7/AM7 -> 0.093934898 | AO7: =AK7/AM7 -> 0.010021685 | AP7: =AL7/AM7 -> 0 | AQ7: =Keys!$C$6/AM7 -> 1 | AR7: =Keys!$C$7/AM7 -> 0.067938858 | AS7: =Keys!$C$8/AM7 -> 0.00010673201 | AT7: =Keys!$C$9/AM7 -> 0 | AU7: =AN7*EXP($G7*INDEX(Costs_BAU!$C$5:$C$52,MATCH($A7,Costs_BAU!$A$5:$A$52,0)))/(AN7*EXP($G7*INDEX(Costs_BAU!$C$5:$C$52,MATCH($A7,Costs_BAU!$A$5:$A$52,0)))+AO7*EXP($G7*INDEX(Costs_BAU!$G$5:$G$52,MATCH($A7,Costs_BAU!$A$5:$A$52,0)))+AP7*EXP($G7*INDEX(Costs_BAU!$I$5:$I$52,MATCH($A7,Costs_BAU!$A$5:$A$52,0)))+AQ7*EXP($G7*INDEX(Costs_BAU!$E$5:$E$52,MATCH($A7,Costs_BAU!$A$5:$A$52,0)))+AR7*EXP($G7*INDEX(Costs_BAU!$F$5:$F$52,MATCH($A7,Costs_BAU!$A$5:$A$52,0)))+AS7*EXP($G7*INDEX(Costs_BAU!$D$5:$D$52,MATCH($A7,Costs_BAU!$A$5:$A$52,0)))+AT7*EXP($G7*INDEX(Costs_BAU!$H$5:$H$52,MATCH($A7,Costs_BAU!$A$5:$A$52,0)))) -> 0.021473816 | AV7: =AO7*EXP($G7*INDEX(Costs_BAU!$G$5:$G$52,MATCH($A7,Costs_BAU!$A$5:$A$52,0)))/(AN7*EXP($G7*INDEX(Costs_BAU!$C$5:$C$52,MATCH($A7,Costs_BAU!$A$5:$A$52,0)))+AO7*EXP($G7*INDEX(Costs_BAU!$G$5:$G$52,MATCH($A7,Costs_BAU!$A$5:$A$52,0)))+AP7*EXP($G7*INDEX(Costs_BAU!$I$5:$I$52,MATCH($A7,Costs_BAU!$A$5:$A$52,0)))+AQ7*EXP($G7*INDEX(Costs_BAU!$E$5:$E$52,MATCH($A7,Costs_BAU!$A$5:$A$52,0)))+AR7*EXP($G7*INDEX(Costs_BAU!$F$5:$F$52,MATCH($A7,Costs_BAU!$A$5:$A$52,0)))+AS7*EXP($G7*INDEX(Costs_BAU!$D$5:$D$52,MATCH($A7,Costs_BAU!$A$5:$A$52,0)))+AT7*EXP($G7*INDEX(Costs_BAU!$H$5:$H$52,MATCH($A7,Costs_BAU!$A$5:$A$52,0)))) -> 0.0078008415 | AW7: =AP7*EXP($G7*INDEX(Costs_BAU!$I$5:$I$52,MATCH($A7,Costs_BAU!$A$5:$A$52,0)))/(AN7*EXP($G7*INDEX(Costs_BAU!$C$5:$C$52,MATCH($A7,Costs_BAU!$A$5:$A$52,0)))+AO7*EXP($G7*INDEX(Costs_BAU!$G$5:$G$52,MATCH($A7,Costs_BAU!$A$5:$A$52,0)))+AP7*EXP($G7*INDEX(Costs_BAU!$I$5:$I$52,MATCH($A7,Costs_BAU!$A$5:$A$52,0)))+AQ7*EXP($G7*INDEX(Costs_BAU!$E$5:$E$52,MATCH($A7,Costs_BAU!$A$5:$A$52,0)))+AR7*EXP($G7*INDEX(Costs_BAU!$F$5:$F$52,MATCH($A7,Costs_BAU!$A$5:$A$52,0)))+AS7*EXP($G7*INDEX(Costs_BAU!$D$5:$D$52,MATCH($A7,Costs_BAU!$A$5:$A$52,0)))+AT7*EXP($G7*INDEX(Costs_BAU!$H$5:$H$52,MATCH($A7,Costs_BAU!$A$5:$A$52,0)))) -> 0 | AX7: =AU7+AV7+AW7 -> 0.029274657 | AY7: =(AX7-$F7)*100 -> 0.35746573
A8: AZ | B8: Arizona | C8: =INDEX(Alliance_2025!$H$5:$H$56,MATCH($A8,Alliance_2025!$A$5:$A$56,0)) -> 0.0759 | D8: =INDEX(Alliance_2025!$G$5:$G$56,MATCH($A8,Alliance_2025!$A$5:$A$56,0)) -> 0.0118 | E8: =INDEX(Alliance_2025!$I$5:$I$56,MATCH($A8,Alliance_2025!$A$5:$A$56,0)) -> 0 | F8: =C8+D8+E8 -> 0.0877 | G8: =Keys!$C$4 -> -8 | I8: =IF(INDEX(Costs_BAU!$E$5:$E$52,MATCH($A8,Costs_BAU!$A$5:$A$52,0))>Keys!$C$5,0,Keys!$C$6*EXP($G8*INDEX(Costs_BAU!$E$5:$E$52,MATCH($A8,Costs_BAU!$A$5:$A$52,0)))) -> 0.016170996 | J8: =IF(INDEX(Costs_BAU!$F$5:$F$52,MATCH($A8,Costs_BAU!$A$5:$A$52,0))>Keys!$C$5,0,Keys!$C$7*EXP($G8*INDEX(Costs_BAU!$F$5:$F$52,MATCH($A8,Costs_BAU!$A$5:$A$52,0)))) -> 0.00063775579 | K8: =IF(INDEX(Costs_BAU!$D$5:$D$52,MATCH($A8,Costs_BAU!$A$5:$A$52,0))>Keys!$C$5,0,Keys!$C$8*EXP($G8*INDEX(Costs_BAU!$D$5:$D$52,MATCH($A8,Costs_BAU!$A$5:$A$52,0)))) -> 1.296164e-06 | L8: =IF(INDEX(Costs_BAU!$H$5:$H$52,MATCH($A8,Costs_BAU!$A$5:$A$52,0))>Keys!$C$5,0,Keys!$C$9*EXP($G8*INDEX(Costs_BAU!$H$5:$H$52,MATCH($A8,Costs_BAU!$A$5:$A$52,0)))) -> 0 | M8: =SUM(I8:L8) -> 0.016810048 | N8: =M8/(1-F8) -> 0.018426009 | O8: =$C8*$N8*EXP(-$G8*INDEX(Costs_BAU!$C$5:$C$52,MATCH($A8,Costs_BAU!$A$5:$A$52,0))) -> 0.31075866 | P8: =$D8*$N8*EXP(-$G8*INDEX(Costs_BAU!$G$5:$G$52,MATCH($A8,Costs_BAU!$A$5:$A$52,0))) -> 0.015901723 | Q8: =$E8*$N8*EXP(-$G8*INDEX(Costs_BAU!$I$5:$I$52,MATCH($A8,Costs_BAU!$A$5:$A$52,0))) -> 0 | R8: =MAX(Keys!$C$15,O8,P8,Q8) -> 1 | S8: =O8/$R8 -> 0.31075866 | T8: =P8/$R8 -> 0.015901723 | U8: =Q8/$R8 -> 0 | V8: =Keys!$C$6/$R8 -> 1 | W8: =Keys!$C$7/$R8 -> 0.067938858 | X8: =Keys!$C$8/$R8 -> 0.00010673201 | Y8: =Keys!$C$9/$R8 -> 0 | Z8: =S8*EXP($G8*INDEX(Costs_BAU!$C$5:$C$52,MATCH($A8,Costs_BAU!$A$5:$A$52,0)))/(S8*EXP($G8*INDEX(Costs_BAU!$C$5:$C$52,MATCH($A8,Costs_BAU!$A$5:$A$52,0)))+T8*EXP($G8*INDEX(Costs_BAU!$G$5:$G$52,MATCH($A8,Costs_BAU!$A$5:$A$52,0)))+U8*EXP($G8*INDEX(Costs_BAU!$I$5:$I$52,MATCH($A8,Costs_BAU!$A$5:$A$52,0)))+V8*EXP($G8*INDEX(Costs_BAU!$E$5:$E$52,MATCH($A8,Costs_BAU!$A$5:$A$52,0)))+W8*EXP($G8*INDEX(Costs_BAU!$F$5:$F$52,MATCH($A8,Costs_BAU!$A$5:$A$52,0)))+X8*EXP($G8*INDEX(Costs_BAU!$D$5:$D$52,MATCH($A8,Costs_BAU!$A$5:$A$52,0)))+Y8*EXP($G8*INDEX(Costs_BAU!$H$5:$H$52,MATCH($A8,Costs_BAU!$A$5:$A$52,0)))) -> 0.0759 | AA8: =T8*EXP($G8*INDEX(Costs_BAU!$G$5:$G$52,MATCH($A8,Costs_BAU!$A$5:$A$52,0)))/(S8*EXP($G8*INDEX(Costs_BAU!$C$5:$C$52,MATCH($A8,Costs_BAU!$A$5:$A$52,0)))+T8*EXP($G8*INDEX(Costs_BAU!$G$5:$G$52,MATCH($A8,Costs_BAU!$A$5:$A$52,0)))+U8*EXP($G8*INDEX(Costs_BAU!$I$5:$I$52,MATCH($A8,Costs_BAU!$A$5:$A$52,0)))+V8*EXP($G8*INDEX(Costs_BAU!$E$5:$E$52,MATCH($A8,Costs_BAU!$A$5:$A$52,0)))+W8*EXP($G8*INDEX(Costs_BAU!$F$5:$F$52,MATCH($A8,Costs_BAU!$A$5:$A$52,0)))+X8*EXP($G8*INDEX(Costs_BAU!$D$5:$D$52,MATCH($A8,Costs_BAU!$A$5:$A$52,0)))+Y8*EXP($G8*INDEX(Costs_BAU!$H$5:$H$52,MATCH($A8,Costs_BAU!$A$5:$A$52,0)))) -> 0.0118 | AB8: =U8*EXP($G8*INDEX(Costs_BAU!$I$5:$I$52,MATCH($A8,Costs_BAU!$A$5:$A$52,0)))/(S8*EXP($G8*INDEX(Costs_BAU!$C$5:$C$52,MATCH($A8,Costs_BAU!$A$5:$A$52,0)))+T8*EXP($G8*INDEX(Costs_BAU!$G$5:$G$52,MATCH($A8,Costs_BAU!$A$5:$A$52,0)))+U8*EXP($G8*INDEX(Costs_BAU!$I$5:$I$52,MATCH($A8,Costs_BAU!$A$5:$A$52,0)))+V8*EXP($G8*INDEX(Costs_BAU!$E$5:$E$52,MATCH($A8,Costs_BAU!$A$5:$A$52,0)))+W8*EXP($G8*INDEX(Costs_BAU!$F$5:$F$52,MATCH($A8,Costs_BAU!$A$5:$A$52,0)))+X8*EXP($G8*INDEX(Costs_BAU!$D$5:$D$52,MATCH($A8,Costs_BAU!$A$5:$A$52,0)))+Y8*EXP($G8*INDEX(Costs_BAU!$H$5:$H$52,MATCH($A8,Costs_BAU!$A$5:$A$52,0)))) -> 0 | AC8: =MAX(ABS(Z8-C8),ABS(AA8-D8),ABS(AB8-E8)) -> 0 | AD8: =IF(AC8>Keys!$C$14,"SHARE MISMATCH",IF(ABS(MAX(S8:Y8)-Keys!$C$15)>Keys!$C$14,"MAX WEIGHT <> 1",IF(R8>Keys!$C$15,"ok (rescaled)","ok"))) -> ok | AF8: 2 | AG8: =IF(O8>0,LOG10(O8),"") -> -0.50757675 | AH8: =IF(P8>0,LOG10(P8),"") -> -1.7985558 | AI8: =IF(Q8>0,LOG10(Q8),"") | AJ8: =IFERROR(10^AVERAGEIF($AF$6:$AF$53,AF8,$AG$6:$AG$53),0) -> 0.2499031 | AK8: =IFERROR(10^AVERAGEIF($AF$6:$AF$53,AF8,$AH$6:$AH$53),0) -> 0.022961157 | AL8: =IFERROR(10^AVERAGEIF($AF$6:$AF$53,AF8,$AI$6:$AI$53),0) -> 0 | AM8: =MAX(1,AJ8,AK8,AL8) -> 1 | AN8: =AJ8/AM8 -> 0.2499031 | AO8: =AK8/AM8 -> 0.022961157 | AP8: =AL8/AM8 -> 0 | AQ8: =Keys!$C$6/AM8 -> 1 | AR8: =Keys!$C$7/AM8 -> 0.067938858 | AS8: =Keys!$C$8/AM8 -> 0.00010673201 | AT8: =Keys!$C$9/AM8 -> 0 | AU8: =AN8*EXP($G8*INDEX(Costs_BAU!$C$5:$C$52,MATCH($A8,Costs_BAU!$A$5:$A$52,0)))/(AN8*EXP($G8*INDEX(Costs_BAU!$C$5:$C$52,MATCH($A8,Costs_BAU!$A$5:$A$52,0)))+AO8*EXP($G8*INDEX(Costs_BAU!$G$5:$G$52,MATCH($A8,Costs_BAU!$A$5:$A$52,0)))+AP8*EXP($G8*INDEX(Costs_BAU!$I$5:$I$52,MATCH($A8,Costs_BAU!$A$5:$A$52,0)))+AQ8*EXP($G8*INDEX(Costs_BAU!$E$5:$E$52,MATCH($A8,Costs_BAU!$A$5:$A$52,0)))+AR8*EXP($G8*INDEX(Costs_BAU!$F$5:$F$52,MATCH($A8,Costs_BAU!$A$5:$A$52,0)))+AS8*EXP($G8*INDEX(Costs_BAU!$D$5:$D$52,MATCH($A8,Costs_BAU!$A$5:$A$52,0)))+AT8*EXP($G8*INDEX(Costs_BAU!$H$5:$H$52,MATCH($A8,Costs_BAU!$A$5:$A$52,0)))) -> 0.061629758 | AV8: =AO8*EXP($G8*INDEX(Costs_BAU!$G$5:$G$52,MATCH($A8,Costs_BAU!$A$5:$A$52,0)))/(AN8*EXP($G8*INDEX(Costs_BAU!$C$5:$C$52,MATCH($A8,Costs_BAU!$A$5:$A$52,0)))+AO8*EXP($G8*INDEX(Costs_BAU!$G$5:$G$52,MATCH($A8,Costs_BAU!$A$5:$A$52,0)))+AP8*EXP($G8*INDEX(Costs_BAU!$I$5:$I$52,MATCH($A8,Costs_BAU!$A$5:$A$52,0)))+AQ8*EXP($G8*INDEX(Costs_BAU!$E$5:$E$52,MATCH($A8,Costs_BAU!$A$5:$A$52,0)))+AR8*EXP($G8*INDEX(Costs_BAU!$F$5:$F$52,MATCH($A8,Costs_BAU!$A$5:$A$52,0)))+AS8*EXP($G8*INDEX(Costs_BAU!$D$5:$D$52,MATCH($A8,Costs_BAU!$A$5:$A$52,0)))+AT8*EXP($G8*INDEX(Costs_BAU!$H$5:$H$52,MATCH($A8,Costs_BAU!$A$5:$A$52,0)))) -> 0.017204097 | AW8: =AP8*EXP($G8*INDEX(Costs_BAU!$I$5:$I$52,MATCH($A8,Costs_BAU!$A$5:$A$52,0)))/(AN8*EXP($G8*INDEX(Costs_BAU!$C$5:$C$52,MATCH($A8,Costs_BAU!$A$5:$A$52,0)))+AO8*EXP($G8*INDEX(Costs_BAU!$G$5:$G$52,MATCH($A8,Costs_BAU!$A$5:$A$52,0)))+AP8*EXP($G8*INDEX(Costs_BAU!$I$5:$I$52,MATCH($A8,Costs_BAU!$A$5:$A$52,0)))+AQ8*EXP($G8*INDEX(Costs_BAU!$E$5:$E$52,MATCH($A8,Costs_BAU!$A$5:$A$52,0)))+AR8*EXP($G8*INDEX(Costs_BAU!$F$5:$F$52,MATCH($A8,Costs_BAU!$A$5:$A$52,0)))+AS8*EXP($G8*INDEX(Costs_BAU!$D$5:$D$52,MATCH($A8,Costs_BAU!$A$5:$A$52,0)))+AT8*EXP($G8*INDEX(Costs_BAU!$H$5:$H$52,MATCH($A8,Costs_BAU!$A$5:$A$52,0)))) -> 0 | AX8: =AU8+AV8+AW8 -> 0.078833855 | AY8: =(AX8-$F8)*100 -> -0.8866145
A9: CA | B9: California | C9: =INDEX(Alliance_2025!$H$5:$H$56,MATCH($A9,Alliance_2025!$A$5:$A$56,0)) -> 0.2042 | D9: =INDEX(Alliance_2025!$G$5:$G$56,MATCH($A9,Alliance_2025!$A$5:$A$56,0)) -> 0.0342 | E9: =INDEX(Alliance_2025!$I$5:$I$56,MATCH($A9,Alliance_2025!$A$5:$A$56,0)) -> 0.0002 | F9: =C9+D9+E9 -> 0.2386 | G9: =Keys!$C$4 -> -8 | I9: =IF(INDEX(Costs_BAU!$E$5:$E$52,MATCH($A9,Costs_BAU!$A$5:$A$52,0))>Keys!$C$5,0,Keys!$C$6*EXP($G9*INDEX(Costs_BAU!$E$5:$E$52,MATCH($A9,Costs_BAU!$A$5:$A$52,0)))) -> 0.01367995 | J9: =IF(INDEX(Costs_BAU!$F$5:$F$52,MATCH($A9,Costs_BAU!$A$5:$A$52,0))>Keys!$C$5,0,Keys!$C$7*EXP($G9*INDEX(Costs_BAU!$F$5:$F$52,MATCH($A9,Costs_BAU!$A$5:$A$52,0)))) -> 0.0004944685 | K9: =IF(INDEX(Costs_BAU!$D$5:$D$52,MATCH($A9,Costs_BAU!$A$5:$A$52,0))>Keys!$C$5,0,Keys!$C$8*EXP($G9*INDEX(Costs_BAU!$D$5:$D$52,MATCH($A9,Costs_BAU!$A$5:$A$52,0)))) -> 1.04202e-06 | L9: =IF(INDEX(Costs_BAU!$H$5:$H$52,MATCH($A9,Costs_BAU!$A$5:$A$52,0))>Keys!$C$5,0,Keys!$C$9*EXP($G9*INDEX(Costs_BAU!$H$5:$H$52,MATCH($A9,Costs_BAU!$A$5:$A$52,0)))) -> 0 | M9: =SUM(I9:L9) -> 0.014175461 | N9: =M9/(1-F9) -> 0.018617626 | O9: =$C9*$N9*EXP(-$G9*INDEX(Costs_BAU!$C$5:$C$52,MATCH($A9,Costs_BAU!$A$5:$A$52,0))) -> 1.161465 | P9: =$D9*$N9*EXP(-$G9*INDEX(Costs_BAU!$G$5:$G$52,MATCH($A9,Costs_BAU!$A$5:$A$52,0))) -> 0.070144343 | Q9: =$E9*$N9*EXP(-$G9*INDEX(Costs_BAU!$I$5:$I$52,MATCH($A9,Costs_BAU!$A$5:$A$52,0))) -> 0.00089567254 | R9: =MAX(Keys!$C$15,O9,P9,Q9) -> 1.161465 | S9: =O9/$R9 -> 1 | T9: =P9/$R9 -> 0.060392989 | U9: =Q9/$R9 -> 0.00077115758 | V9: =Keys!$C$6/$R9 -> 0.8609816 | W9: =Keys!$C$7/$R9 -> 0.058494107 | X9: =Keys!$C$8/$R9 -> 9.1894296e-05 | Y9: =Keys!$C$9/$R9 -> 0 | Z9: =S9*EXP($G9*INDEX(Costs_BAU!$C$5:$C$52,MATCH($A9,Costs_BAU!$A$5:$A$52,0)))/(S9*EXP($G9*INDEX(Costs_BAU!$C$5:$C$52,MATCH($A9,Costs_BAU!$A$5:$A$52,0)))+T9*EXP($G9*INDEX(Costs_BAU!$G$5:$G$52,MATCH($A9,Costs_BAU!$A$5:$A$52,0)))+U9*EXP($G9*INDEX(Costs_BAU!$I$5:$I$52,MATCH($A9,Costs_BAU!$A$5:$A$52,0)))+V9*EXP($G9*INDEX(Costs_BAU!$E$5:$E$52,MATCH($A9,Costs_BAU!$A$5:$A$52,0)))+W9*EXP($G9*INDEX(Costs_BAU!$F$5:$F$52,MATCH($A9,Costs_BAU!$A$5:$A$52,0)))+X9*EXP($G9*INDEX(Costs_BAU!$D$5:$D$52,MATCH($A9,Costs_BAU!$A$5:$A$52,0)))+Y9*EXP($G9*INDEX(Costs_BAU!$H$5:$H$52,MATCH($A9,Costs_BAU!$A$5:$A$52,0)))) -> 0.2042 | AA9: =T9*EXP($G9*INDEX(Costs_BAU!$G$5:$G$52,MATCH($A9,Costs_BAU!$A$5:$A$52,0)))/(S9*EXP($G9*INDEX(Costs_BAU!$C$5:$C$52,MATCH($A9,Costs_BAU!$A$5:$A$52,0)))+T9*EXP($G9*INDEX(Costs_BAU!$G$5:$G$52,MATCH($A9,Costs_BAU!$A$5:$A$52,0)))+U9*EXP($G9*INDEX(Costs_BAU!$I$5:$I$52,MATCH($A9,Costs_BAU!$A$5:$A$52,0)))+V9*EXP($G9*INDEX(Costs_BAU!$E$5:$E$52,MATCH($A9,Costs_BAU!$A$5:$A$52,0)))+W9*EXP($G9*INDEX(Costs_BAU!$F$5:$F$52,MATCH($A9,Costs_BAU!$A$5:$A$52,0)))+X9*EXP($G9*INDEX(Costs_BAU!$D$5:$D$52,MATCH($A9,Costs_BAU!$A$5:$A$52,0)))+Y9*EXP($G9*INDEX(Costs_BAU!$H$5:$H$52,MATCH($A9,Costs_BAU!$A$5:$A$52,0)))) -> 0.0342 | AB9: =U9*EXP($G9*INDEX(Costs_BAU!$I$5:$I$52,MATCH($A9,Costs_BAU!$A$5:$A$52,0)))/(S9*EXP($G9*INDEX(Costs_BAU!$C$5:$C$52,MATCH($A9,Costs_BAU!$A$5:$A$52,0)))+T9*EXP($G9*INDEX(Costs_BAU!$G$5:$G$52,MATCH($A9,Costs_BAU!$A$5:$A$52,0)))+U9*EXP($G9*INDEX(Costs_BAU!$I$5:$I$52,MATCH($A9,Costs_BAU!$A$5:$A$52,0)))+V9*EXP($G9*INDEX(Costs_BAU!$E$5:$E$52,MATCH($A9,Costs_BAU!$A$5:$A$52,0)))+W9*EXP($G9*INDEX(Costs_BAU!$F$5:$F$52,MATCH($A9,Costs_BAU!$A$5:$A$52,0)))+X9*EXP($G9*INDEX(Costs_BAU!$D$5:$D$52,MATCH($A9,Costs_BAU!$A$5:$A$52,0)))+Y9*EXP($G9*INDEX(Costs_BAU!$H$5:$H$52,MATCH($A9,Costs_BAU!$A$5:$A$52,0)))) -> 0.0002 | AC9: =MAX(ABS(Z9-C9),ABS(AA9-D9),ABS(AB9-E9)) -> 2.7755576e-17 | AD9: =IF(AC9>Keys!$C$14,"SHARE MISMATCH",IF(ABS(MAX(S9:Y9)-Keys!$C$15)>Keys!$C$14,"MAX WEIGHT <> 1",IF(R9>Keys!$C$15,"ok (rescaled)","ok"))) -> ok (rescaled) | AF9: 4 | AG9: =IF(O9>0,LOG10(O9),"") -> 0.065006128 | AH9: =IF(P9>0,LOG10(P9),"") -> -1.1540073 | AI9: =IF(Q9>0,LOG10(Q9),"") -> -3.0478507 | AJ9: =IFERROR(10^AVERAGEIF($AF$6:$AF$53,AF9,$AG$6:$AG$53),0) -> 1.1336988 | AK9: =IFERROR(10^AVERAGEIF($AF$6:$AF$53,AF9,$AH$6:$AH$53),0) -> 0.057986931 | AL9: =IFERROR(10^AVERAGEIF($AF$6:$AF$53,AF9,$AI$6:$AI$53),0) -> 0.00089567254 | AM9: =MAX(1,AJ9,AK9,AL9) -> 1.1336988 | AN9: =AJ9/AM9 -> 1 | AO9: =AK9/AM9 -> 0.051148447 | AP9: =AL9/AM9 -> 0.00079004457 | AQ9: =Keys!$C$6/AM9 -> 0.88206854 | AR9: =Keys!$C$7/AM9 -> 0.059926729 | AS9: =Keys!$C$8/AM9 -> 9.4144947e-05 | AT9: =Keys!$C$9/AM9 -> 0 | AU9: =AN9*EXP($G9*INDEX(Costs_BAU!$C$5:$C$52,MATCH($A9,Costs_BAU!$A$5:$A$52,0)))/(AN9*EXP($G9*INDEX(Costs_BAU!$C$5:$C$52,MATCH($A9,Costs_BAU!$A$5:$A$52,0)))+AO9*EXP($G9*INDEX(Costs_BAU!$G$5:$G$52,MATCH($A9,Costs_BAU!$A$5:$A$52,0)))+AP9*EXP($G9*INDEX(Costs_BAU!$I$5:$I$52,MATCH($A9,Costs_BAU!$A$5:$A$52,0)))+AQ9*EXP($G9*INDEX(Costs_BAU!$E$5:$E$52,MATCH($A9,Costs_BAU!$A$5:$A$52,0)))+AR9*EXP($G9*INDEX(Costs_BAU!$F$5:$F$52,MATCH($A9,Costs_BAU!$A$5:$A$52,0)))+AS9*EXP($G9*INDEX(Costs_BAU!$D$5:$D$52,MATCH($A9,Costs_BAU!$A$5:$A$52,0)))+AT9*EXP($G9*INDEX(Costs_BAU!$H$5:$H$52,MATCH($A9,Costs_BAU!$A$5:$A$52,0)))) -> 0.20149636 | AV9: =AO9*EXP($G9*INDEX(Costs_BAU!$G$5:$G$52,MATCH($A9,Costs_BAU!$A$5:$A$52,0)))/(AN9*EXP($G9*INDEX(Costs_BAU!$C$5:$C$52,MATCH($A9,Costs_BAU!$A$5:$A$52,0)))+AO9*EXP($G9*INDEX(Costs_BAU!$G$5:$G$52,MATCH($A9,Costs_BAU!$A$5:$A$52,0)))+AP9*EXP($G9*INDEX(Costs_BAU!$I$5:$I$52,MATCH($A9,Costs_BAU!$A$5:$A$52,0)))+AQ9*EXP($G9*INDEX(Costs_BAU!$E$5:$E$52,MATCH($A9,Costs_BAU!$A$5:$A$52,0)))+AR9*EXP($G9*INDEX(Costs_BAU!$F$5:$F$52,MATCH($A9,Costs_BAU!$A$5:$A$52,0)))+AS9*EXP($G9*INDEX(Costs_BAU!$D$5:$D$52,MATCH($A9,Costs_BAU!$A$5:$A$52,0)))+AT9*EXP($G9*INDEX(Costs_BAU!$H$5:$H$52,MATCH($A9,Costs_BAU!$A$5:$A$52,0)))) -> 0.028581401 | AW9: =AP9*EXP($G9*INDEX(Costs_BAU!$I$5:$I$52,MATCH($A9,Costs_BAU!$A$5:$A$52,0)))/(AN9*EXP($G9*INDEX(Costs_BAU!$C$5:$C$52,MATCH($A9,Costs_BAU!$A$5:$A$52,0)))+AO9*EXP($G9*INDEX(Costs_BAU!$G$5:$G$52,MATCH($A9,Costs_BAU!$A$5:$A$52,0)))+AP9*EXP($G9*INDEX(Costs_BAU!$I$5:$I$52,MATCH($A9,Costs_BAU!$A$5:$A$52,0)))+AQ9*EXP($G9*INDEX(Costs_BAU!$E$5:$E$52,MATCH($A9,Costs_BAU!$A$5:$A$52,0)))+AR9*EXP($G9*INDEX(Costs_BAU!$F$5:$F$52,MATCH($A9,Costs_BAU!$A$5:$A$52,0)))+AS9*EXP($G9*INDEX(Costs_BAU!$D$5:$D$52,MATCH($A9,Costs_BAU!$A$5:$A$52,0)))+AT9*EXP($G9*INDEX(Costs_BAU!$H$5:$H$52,MATCH($A9,Costs_BAU!$A$5:$A$52,0)))) -> 0.00020218546 | AX9: =AU9+AV9+AW9 -> 0.23027995 | AY9: =(AX9-$F9)*100 -> -0.83200528
A10: CO | B10: Colorado | C10: =INDEX(Alliance_2025!$H$5:$H$56,MATCH($A10,Alliance_2025!$A$5:$A$56,0)) -> 0.1562 | D10: =INDEX(Alliance_2025!$G$5:$G$56,MATCH($A10,Alliance_2025!$A$5:$A$56,0)) -> 0.0423 | E10: =INDEX(Alliance_2025!$I$5:$I$56,MATCH($A10,Alliance_2025!$A$5:$A$56,0)) -> 0 | F10: =C10+D10+E10 -> 0.1985 | G10: =Keys!$C$4 -> -8 | I10: =IF(INDEX(Costs_BAU!$E$5:$E$52,MATCH($A10,Costs_BAU!$A$5:$A$52,0))>Keys!$C$5,0,Keys!$C$6*EXP($G10*INDEX(Costs_BAU!$E$5:$E$52,MATCH($A10,Costs_BAU!$A$5:$A$52,0)))) -> 0.016675879 | J10: =IF(INDEX(Costs_BAU!$F$5:$F$52,MATCH($A10,Costs_BAU!$A$5:$A$52,0))>Keys!$C$5,0,Keys!$C$7*EXP($G10*INDEX(Costs_BAU!$F$5:$F$52,MATCH($A10,Costs_BAU!$A$5:$A$52,0)))) -> 0.00062203443 | K10: =IF(INDEX(Costs_BAU!$D$5:$D$52,MATCH($A10,Costs_BAU!$A$5:$A$52,0))>Keys!$C$5,0,Keys!$C$8*EXP($G10*INDEX(Costs_BAU!$D$5:$D$52,MATCH($A10,Costs_BAU!$A$5:$A$52,0)))) -> 1.1922772e-06 | L10: =IF(INDEX(Costs_BAU!$H$5:$H$52,MATCH($A10,Costs_BAU!$A$5:$A$52,0))>Keys!$C$5,0,Keys!$C$9*EXP($G10*INDEX(Costs_BAU!$H$5:$H$52,MATCH($A10,Costs_BAU!$A$5:$A$52,0)))) -> 0 | M10: =SUM(I10:L10) -> 0.017299105 | N10: =M10/(1-F10) -> 0.021583413 | O10: =$C10*$N10*EXP(-$G10*INDEX(Costs_BAU!$C$5:$C$52,MATCH($A10,Costs_BAU!$A$5:$A$52,0))) -> 0.66034013 | P10: =$D10*$N10*EXP(-$G10*INDEX(Costs_BAU!$G$5:$G$52,MATCH($A10,Costs_BAU!$A$5:$A$52,0))) -> 0.058682461 | Q10: =$E10*$N10*EXP(-$G10*INDEX(Costs_BAU!$I$5:$I$52,MATCH($A10,Costs_BAU!$A$5:$A$52,0))) -> 0 | R10: =MAX(Keys!$C$15,O10,P10,Q10) -> 1 | S10: =O10/$R10 -> 0.66034013 | T10: =P10/$R10 -> 0.058682461 | U10: =Q10/$R10 -> 0 | V10: =Keys!$C$6/$R10 -> 1 | W10: =Keys!$C$7/$R10 -> 0.067938858 | X10: =Keys!$C$8/$R10 -> 0.00010673201 | Y10: =Keys!$C$9/$R10 -> 0 | Z10: =S10*EXP($G10*INDEX(Costs_BAU!$C$5:$C$52,MATCH($A10,Costs_BAU!$A$5:$A$52,0)))/(S10*EXP($G10*INDEX(Costs_BAU!$C$5:$C$52,MATCH($A10,Costs_BAU!$A$5:$A$52,0)))+T10*EXP($G10*INDEX(Costs_BAU!$G$5:$G$52,MATCH($A10,Costs_BAU!$A$5:$A$52,0)))+U10*EXP($G10*INDEX(Costs_BAU!$I$5:$I$52,MATCH($A10,Costs_BAU!$A$5:$A$52,0)))+V10*EXP($G10*INDEX(Costs_BAU!$E$5:$E$52,MATCH($A10,Costs_BAU!$A$5:$A$52,0)))+W10*EXP($G10*INDEX(Costs_BAU!$F$5:$F$52,MATCH($A10,Costs_BAU!$A$5:$A$52,0)))+X10*EXP($G10*INDEX(Costs_BAU!$D$5:$D$52,MATCH($A10,Costs_BAU!$A$5:$A$52,0)))+Y10*EXP($G10*INDEX(Costs_BAU!$H$5:$H$52,MATCH($A10,Costs_BAU!$A$5:$A$52,0)))) -> 0.1562 | AA10: =T10*EXP($G10*INDEX(Costs_BAU!$G$5:$G$52,MATCH($A10,Costs_BAU!$A$5:$A$52,0)))/(S10*EXP($G10*INDEX(Costs_BAU!$C$5:$C$52,MATCH($A10,Costs_BAU!$A$5:$A$52,0)))+T10*EXP($G10*INDEX(Costs_BAU!$G$5:$G$52,MATCH($A10,Costs_BAU!$A$5:$A$52,0)))+U10*EXP($G10*INDEX(Costs_BAU!$I$5:$I$52,MATCH($A10,Costs_BAU!$A$5:$A$52,0)))+V10*EXP($G10*INDEX(Costs_BAU!$E$5:$E$52,MATCH($A10,Costs_BAU!$A$5:$A$52,0)))+W10*EXP($G10*INDEX(Costs_BAU!$F$5:$F$52,MATCH($A10,Costs_BAU!$A$5:$A$52,0)))+X10*EXP($G10*INDEX(Costs_BAU!$D$5:$D$52,MATCH($A10,Costs_BAU!$A$5:$A$52,0)))+Y10*EXP($G10*INDEX(Costs_BAU!$H$5:$H$52,MATCH($A10,Costs_BAU!$A$5:$A$52,0)))) -> 0.0423 | AB10: =U10*EXP($G10*INDEX(Costs_BAU!$I$5:$I$52,MATCH($A10,Costs_BAU!$A$5:$A$52,0)))/(S10*EXP($G10*INDEX(Costs_BAU!$C$5:$C$52,MATCH($A10,Costs_BAU!$A$5:$A$52,0)))+T10*EXP($G10*INDEX(Costs_BAU!$G$5:$G$52,MATCH($A10,Costs_BAU!$A$5:$A$52,0)))+U10*EXP($G10*INDEX(Costs_BAU!$I$5:$I$52,MATCH($A10,Costs_BAU!$A$5:$A$52,0)))+V10*EXP($G10*INDEX(Costs_BAU!$E$5:$E$52,MATCH($A10,Costs_BAU!$A$5:$A$52,0)))+W10*EXP($G10*INDEX(Costs_BAU!$F$5:$F$52,MATCH($A10,Costs_BAU!$A$5:$A$52,0)))+X10*EXP($G10*INDEX(Costs_BAU!$D$5:$D$52,MATCH($A10,Costs_BAU!$A$5:$A$52,0)))+Y10*EXP($G10*INDEX(Costs_BAU!$H$5:$H$52,MATCH($A10,Costs_BAU!$A$5:$A$52,0)))) -> 0 | AC10: =MAX(ABS(Z10-C10),ABS(AA10-D10),ABS(AB10-E10)) -> 0 | AD10: =IF(AC10>Keys!$C$14,"SHARE MISMATCH",IF(ABS(MAX(S10:Y10)-Keys!$C$15)>Keys!$C$14,"MAX WEIGHT <> 1",IF(R10>Keys!$C$15,"ok (rescaled)","ok"))) -> ok | AF10: 3 | AG10: =IF(O10>0,LOG10(O10),"") -> -0.18023231 | AH10: =IF(P10>0,LOG10(P10),"") -> -1.2314917 | AI10: =IF(Q10>0,LOG10(Q10),"") | AJ10: =IFERROR(10^AVERAGEIF($AF$6:$AF$53,AF10,$AG$6:$AG$53),0) -> 0.67200277 | AK10: =IFERROR(10^AVERAGEIF($AF$6:$AF$53,AF10,$AH$6:$AH$53),0) -> 0.044574547 | AL10: =IFERROR(10^AVERAGEIF($AF$6:$AF$53,AF10,$AI$6:$AI$53),0) -> 0 | AM10: =MAX(1,AJ10,AK10,AL10) -> 1 | AN10: =AJ10/AM10 -> 0.67200277 | AO10: =AK10/AM10 -> 0.044574547 | AP10: =AL10/AM10 -> 0 | AQ10: =Keys!$C$6/AM10 -> 1 | AR10: =Keys!$C$7/AM10 -> 0.067938858 | AS10: =Keys!$C$8/AM10 -> 0.00010673201 | AT10: =Keys!$C$9/AM10 -> 0 | AU10: =AN10*EXP($G10*INDEX(Costs_BAU!$C$5:$C$52,MATCH($A10,Costs_BAU!$A$5:$A$52,0)))/(AN10*EXP($G10*INDEX(Costs_BAU!$C$5:$C$52,MATCH($A10,Costs_BAU!$A$5:$A$52,0)))+AO10*EXP($G10*INDEX(Costs_BAU!$G$5:$G$52,MATCH($A10,Costs_BAU!$A$5:$A$52,0)))+AP10*EXP($G10*INDEX(Costs_BAU!$I$5:$I$52,MATCH($A10,Costs_BAU!$A$5:$A$52,0)))+AQ10*EXP($G10*INDEX(Costs_BAU!$E$5:$E$52,MATCH($A10,Costs_BAU!$A$5:$A$52,0)))+AR10*EXP($G10*INDEX(Costs_BAU!$F$5:$F$52,MATCH($A10,Costs_BAU!$A$5:$A$52,0)))+AS10*EXP($G10*INDEX(Costs_BAU!$D$5:$D$52,MATCH($A10,Costs_BAU!$A$5:$A$52,0)))+AT10*EXP($G10*INDEX(Costs_BAU!$H$5:$H$52,MATCH($A10,Costs_BAU!$A$5:$A$52,0)))) -> 0.16014552 | AV10: =AO10*EXP($G10*INDEX(Costs_BAU!$G$5:$G$52,MATCH($A10,Costs_BAU!$A$5:$A$52,0)))/(AN10*EXP($G10*INDEX(Costs_BAU!$C$5:$C$52,MATCH($A10,Costs_BAU!$A$5:$A$52,0)))+AO10*EXP($G10*INDEX(Costs_BAU!$G$5:$G$52,MATCH($A10,Costs_BAU!$A$5:$A$52,0)))+AP10*EXP($G10*INDEX(Costs_BAU!$I$5:$I$52,MATCH($A10,Costs_BAU!$A$5:$A$52,0)))+AQ10*EXP($G10*INDEX(Costs_BAU!$E$5:$E$52,MATCH($A10,Costs_BAU!$A$5:$A$52,0)))+AR10*EXP($G10*INDEX(Costs_BAU!$F$5:$F$52,MATCH($A10,Costs_BAU!$A$5:$A$52,0)))+AS10*EXP($G10*INDEX(Costs_BAU!$D$5:$D$52,MATCH($A10,Costs_BAU!$A$5:$A$52,0)))+AT10*EXP($G10*INDEX(Costs_BAU!$H$5:$H$52,MATCH($A10,Costs_BAU!$A$5:$A$52,0)))) -> 0.032370497 | AW10: =AP10*EXP($G10*INDEX(Costs_BAU!$I$5:$I$52,MATCH($A10,Costs_BAU!$A$5:$A$52,0)))/(AN10*EXP($G10*INDEX(Costs_BAU!$C$5:$C$52,MATCH($A10,Costs_BAU!$A$5:$A$52,0)))+AO10*EXP($G10*INDEX(Costs_BAU!$G$5:$G$52,MATCH($A10,Costs_BAU!$A$5:$A$52,0)))+AP10*EXP($G10*INDEX(Costs_BAU!$I$5:$I$52,MATCH($A10,Costs_BAU!$A$5:$A$52,0)))+AQ10*EXP($G10*INDEX(Costs_BAU!$E$5:$E$52,MATCH($A10,Costs_BAU!$A$5:$A$52,0)))+AR10*EXP($G10*INDEX(Costs_BAU!$F$5:$F$52,MATCH($A10,Costs_BAU!$A$5:$A$52,0)))+AS10*EXP($G10*INDEX(Costs_BAU!$D$5:$D$52,MATCH($A10,Costs_BAU!$A$5:$A$52,0)))+AT10*EXP($G10*INDEX(Costs_BAU!$H$5:$H$52,MATCH($A10,Costs_BAU!$A$5:$A$52,0)))) -> 0 | AX10: =AU10+AV10+AW10 -> 0.19251602 | AY10: =(AX10-$F10)*100 -> -0.59839831
